2021-12-15 13:26:28,860 INFO  * Running on http://127.0.0.1:5000/ (Press CTRL+C to quit)
2021-12-15 13:28:54,887 INFO  * Running on http://127.0.0.1:5000/ (Press CTRL+C to quit)
2021-12-15 13:28:56,794 ERROR Exception on /employees [GET]
Traceback (most recent call last):
  File "C:\Users\itsvi\Desktop\Project1\venv\lib\site-packages\flask\app.py", line 2073, in wsgi_app
    response = self.full_dispatch_request()
  File "C:\Users\itsvi\Desktop\Project1\venv\lib\site-packages\flask\app.py", line 1518, in full_dispatch_request
    rv = self.handle_user_exception(e)
  File "C:\Users\itsvi\Desktop\Project1\venv\lib\site-packages\flask\app.py", line 1516, in full_dispatch_request
    rv = self.dispatch_request()
  File "C:\Users\itsvi\Desktop\Project1\venv\lib\site-packages\flask\app.py", line 1502, in dispatch_request
    return self.ensure_sync(self.view_functions[rule.endpoint])(**req.view_args)
  File "C:\Users\itsvi\Desktop\Project1\main.py", line 20, in get_all_employees
    dictionary_employee = employees.make_employee_dictionary()
AttributeError: 'list' object has no attribute 'make_employee_dictionary'
2021-12-15 13:28:56,840 INFO 127.0.0.1 - - [15/Dec/2021 13:28:56] "[35m[1mGET /employees HTTP/1.1[0m" 500 -
2021-12-15 13:30:55,680 INFO  * Running on http://127.0.0.1:5000/ (Press CTRL+C to quit)
2021-12-15 13:31:00,298 INFO 127.0.0.1 - - [15/Dec/2021 13:31:00] "GET /employees HTTP/1.1" 200 -
2021-12-15 13:32:25,941 INFO 127.0.0.1 - - [15/Dec/2021 13:32:25] "GET /employees HTTP/1.1" 200 -
2021-12-15 15:38:36,903 INFO  * Running on http://127.0.0.1:5000/ (Press CTRL+C to quit)
2021-12-15 15:38:50,905 INFO 127.0.0.1 - - [15/Dec/2021 15:38:50] "[33mGET /employees/login HTTP/1.1[0m" 404 -
2021-12-15 15:38:59,192 INFO 127.0.0.1 - - [15/Dec/2021 15:38:59] "[31m[1mGET /employee/login HTTP/1.1[0m" 405 -
2021-12-15 16:15:58,129 INFO  * Running on http://127.0.0.1:5000/ (Press CTRL+C to quit)
2021-12-15 16:18:45,189 INFO  * Running on http://127.0.0.1:5000/ (Press CTRL+C to quit)
2021-12-15 16:18:52,059 INFO 127.0.0.1 - - [15/Dec/2021 16:18:52] "[31m[1mGET /employee/login HTTP/1.1[0m" 405 -
2021-12-15 16:19:21,021 INFO  * Running on http://127.0.0.1:5000/ (Press CTRL+C to quit)
2021-12-15 16:19:23,471 INFO 127.0.0.1 - - [15/Dec/2021 16:19:23] "[31m[1mGET /employee/login HTTP/1.1[0m" 405 -
2021-12-15 16:23:04,984 ERROR Exception on /employee/login [POST]
Traceback (most recent call last):
  File "C:\Users\itsvi\Desktop\Project1\venv\lib\site-packages\flask\app.py", line 2073, in wsgi_app
    response = self.full_dispatch_request()
  File "C:\Users\itsvi\Desktop\Project1\venv\lib\site-packages\flask\app.py", line 1518, in full_dispatch_request
    rv = self.handle_user_exception(e)
  File "C:\Users\itsvi\Desktop\Project1\venv\lib\site-packages\flask\app.py", line 1516, in full_dispatch_request
    rv = self.dispatch_request()
  File "C:\Users\itsvi\Desktop\Project1\venv\lib\site-packages\flask\app.py", line 1502, in dispatch_request
    return self.ensure_sync(self.view_functions[rule.endpoint])(**req.view_args)
  File "C:\Users\itsvi\Desktop\Project1\main.py", line 31, in service_get_login_for_employee
    #  objects for postman
KeyError: 'employee_Id'
2021-12-15 16:23:04,991 INFO 127.0.0.1 - - [15/Dec/2021 16:23:04] "[35m[1mPOST /employee/login HTTP/1.1[0m" 500 -
2021-12-15 16:23:12,480 INFO  * Running on http://127.0.0.1:5000/ (Press CTRL+C to quit)
2021-12-15 16:23:19,144 ERROR Exception on /employee/login [POST]
Traceback (most recent call last):
  File "C:\Users\itsvi\Desktop\Project1\venv\lib\site-packages\flask\app.py", line 2073, in wsgi_app
    response = self.full_dispatch_request()
  File "C:\Users\itsvi\Desktop\Project1\venv\lib\site-packages\flask\app.py", line 1518, in full_dispatch_request
    rv = self.handle_user_exception(e)
  File "C:\Users\itsvi\Desktop\Project1\venv\lib\site-packages\flask\app.py", line 1516, in full_dispatch_request
    rv = self.dispatch_request()
  File "C:\Users\itsvi\Desktop\Project1\venv\lib\site-packages\flask\app.py", line 1502, in dispatch_request
    return self.ensure_sync(self.view_functions[rule.endpoint])(**req.view_args)
  File "C:\Users\itsvi\Desktop\Project1\main.py", line 32, in service_get_login_for_employee
    employee_id = result["employee_Id"]
KeyError: 'employee_Id'
2021-12-15 16:23:19,147 INFO 127.0.0.1 - - [15/Dec/2021 16:23:19] "[35m[1mPOST /employee/login HTTP/1.1[0m" 500 -
2021-12-15 16:27:09,805 ERROR Exception on /employee/login [POST]
Traceback (most recent call last):
  File "C:\Users\itsvi\Desktop\Project1\venv\lib\site-packages\flask\app.py", line 2073, in wsgi_app
    response = self.full_dispatch_request()
  File "C:\Users\itsvi\Desktop\Project1\venv\lib\site-packages\flask\app.py", line 1518, in full_dispatch_request
    rv = self.handle_user_exception(e)
  File "C:\Users\itsvi\Desktop\Project1\venv\lib\site-packages\flask\app.py", line 1516, in full_dispatch_request
    rv = self.dispatch_request()
  File "C:\Users\itsvi\Desktop\Project1\venv\lib\site-packages\flask\app.py", line 1502, in dispatch_request
    return self.ensure_sync(self.view_functions[rule.endpoint])(**req.view_args)
  File "C:\Users\itsvi\Desktop\Project1\main.py", line 32, in service_get_login_for_employee
    employee_id = result["employee_Id"]
KeyError: 'employee_Id'
2021-12-15 16:27:09,806 INFO 127.0.0.1 - - [15/Dec/2021 16:27:09] "[35m[1mPOST /employee/login HTTP/1.1[0m" 500 -
2021-12-15 16:30:19,804 INFO  * Running on http://127.0.0.1:5000/ (Press CTRL+C to quit)
2021-12-15 16:30:30,268 ERROR Exception on /employee/login [POST]
Traceback (most recent call last):
  File "C:\Users\itsvi\Desktop\Project1\venv\lib\site-packages\flask\app.py", line 2073, in wsgi_app
    response = self.full_dispatch_request()
  File "C:\Users\itsvi\Desktop\Project1\venv\lib\site-packages\flask\app.py", line 1518, in full_dispatch_request
    rv = self.handle_user_exception(e)
  File "C:\Users\itsvi\Desktop\Project1\venv\lib\site-packages\flask\app.py", line 1516, in full_dispatch_request
    rv = self.dispatch_request()
  File "C:\Users\itsvi\Desktop\Project1\venv\lib\site-packages\flask\app.py", line 1502, in dispatch_request
    return self.ensure_sync(self.view_functions[rule.endpoint])(**req.view_args)
  File "C:\Users\itsvi\Desktop\Project1\main.py", line 32, in service_get_login_for_employee
    employee_id = result["employee_Id"]
KeyError: 'employee_Id'
2021-12-15 16:30:30,271 INFO 127.0.0.1 - - [15/Dec/2021 16:30:30] "[35m[1mPOST /employee/login HTTP/1.1[0m" 500 -
2021-12-15 16:32:01,674 INFO  * Running on http://127.0.0.1:5000/ (Press CTRL+C to quit)
2021-12-15 16:32:06,234 ERROR Exception on /employee/login [POST]
Traceback (most recent call last):
  File "C:\Users\itsvi\Desktop\Project1\venv\lib\site-packages\flask\app.py", line 2073, in wsgi_app
    response = self.full_dispatch_request()
  File "C:\Users\itsvi\Desktop\Project1\venv\lib\site-packages\flask\app.py", line 1518, in full_dispatch_request
    rv = self.handle_user_exception(e)
  File "C:\Users\itsvi\Desktop\Project1\venv\lib\site-packages\flask\app.py", line 1516, in full_dispatch_request
    rv = self.dispatch_request()
  File "C:\Users\itsvi\Desktop\Project1\venv\lib\site-packages\flask\app.py", line 1502, in dispatch_request
    return self.ensure_sync(self.view_functions[rule.endpoint])(**req.view_args)
  File "C:\Users\itsvi\Desktop\Project1\main.py", line 36, in service_get_login_for_employee
    return_employee = Employee(employee_Id=employee_id, passcode=employee_passcode)
TypeError: Employee.__init__() got an unexpected keyword argument 'employee_Id'
2021-12-15 16:32:06,236 INFO 127.0.0.1 - - [15/Dec/2021 16:32:06] "[35m[1mPOST /employee/login HTTP/1.1[0m" 500 -
2021-12-15 16:33:48,597 INFO  * Running on http://127.0.0.1:5000/ (Press CTRL+C to quit)
2021-12-15 16:40:52,813 INFO  * Running on http://127.0.0.1:5000/ (Press CTRL+C to quit)
2021-12-15 16:43:52,716 INFO  * Running on http://127.0.0.1:5000/ (Press CTRL+C to quit)
2021-12-15 16:43:57,194 ERROR Exception on /employee/login [POST]
Traceback (most recent call last):
  File "C:\Users\itsvi\Desktop\Project1\venv\lib\site-packages\flask\app.py", line 2073, in wsgi_app
    response = self.full_dispatch_request()
  File "C:\Users\itsvi\Desktop\Project1\venv\lib\site-packages\flask\app.py", line 1518, in full_dispatch_request
    rv = self.handle_user_exception(e)
  File "C:\Users\itsvi\Desktop\Project1\venv\lib\site-packages\flask\app.py", line 1516, in full_dispatch_request
    rv = self.dispatch_request()
  File "C:\Users\itsvi\Desktop\Project1\venv\lib\site-packages\flask\app.py", line 1502, in dispatch_request
    return self.ensure_sync(self.view_functions[rule.endpoint])(**req.view_args)
  File "C:\Users\itsvi\Desktop\Project1\main.py", line 40, in service_get_login_for_employee
    employee_dictionary = return_employee.make_employee_dictionary()
AttributeError: 'NoneType' object has no attribute 'make_employee_dictionary'
2021-12-15 16:43:57,197 INFO 127.0.0.1 - - [15/Dec/2021 16:43:57] "[35m[1mPOST /employee/login HTTP/1.1[0m" 500 -
2021-12-15 16:45:27,963 INFO  * Running on http://127.0.0.1:5000/ (Press CTRL+C to quit)
2021-12-15 16:45:33,150 ERROR Exception on /employee/login [POST]
Traceback (most recent call last):
  File "C:\Users\itsvi\Desktop\Project1\venv\lib\site-packages\flask\app.py", line 2073, in wsgi_app
    response = self.full_dispatch_request()
  File "C:\Users\itsvi\Desktop\Project1\venv\lib\site-packages\flask\app.py", line 1518, in full_dispatch_request
    rv = self.handle_user_exception(e)
  File "C:\Users\itsvi\Desktop\Project1\venv\lib\site-packages\flask\app.py", line 1516, in full_dispatch_request
    rv = self.dispatch_request()
  File "C:\Users\itsvi\Desktop\Project1\venv\lib\site-packages\flask\app.py", line 1502, in dispatch_request
    return self.ensure_sync(self.view_functions[rule.endpoint])(**req.view_args)
  File "C:\Users\itsvi\Desktop\Project1\main.py", line 40, in service_get_login_for_employee
    employee_dictionary = return_employee.make_employee_dictionary()
AttributeError: 'NoneType' object has no attribute 'make_employee_dictionary'
2021-12-15 16:45:33,152 INFO 127.0.0.1 - - [15/Dec/2021 16:45:33] "[35m[1mPOST /employee/login HTTP/1.1[0m" 500 -
2021-12-15 16:51:50,873 INFO  * Running on http://127.0.0.1:5000/ (Press CTRL+C to quit)
2021-12-15 16:51:53,999 ERROR Exception on /employee/login [POST]
Traceback (most recent call last):
  File "C:\Users\itsvi\Desktop\Project1\venv\lib\site-packages\flask\app.py", line 2073, in wsgi_app
    response = self.full_dispatch_request()
  File "C:\Users\itsvi\Desktop\Project1\venv\lib\site-packages\flask\app.py", line 1518, in full_dispatch_request
    rv = self.handle_user_exception(e)
  File "C:\Users\itsvi\Desktop\Project1\venv\lib\site-packages\flask\app.py", line 1516, in full_dispatch_request
    rv = self.dispatch_request()
  File "C:\Users\itsvi\Desktop\Project1\venv\lib\site-packages\flask\app.py", line 1502, in dispatch_request
    return self.ensure_sync(self.view_functions[rule.endpoint])(**req.view_args)
  File "C:\Users\itsvi\Desktop\Project1\main.py", line 40, in service_get_login_for_employee
    employee_dictionary = return_employee.make_employee_dictionary()
AttributeError: 'NoneType' object has no attribute 'make_employee_dictionary'
2021-12-15 16:51:54,002 INFO 127.0.0.1 - - [15/Dec/2021 16:51:54] "[35m[1mPOST /employee/login HTTP/1.1[0m" 500 -
2021-12-15 16:53:09,780 INFO  * Running on http://127.0.0.1:5000/ (Press CTRL+C to quit)
2021-12-15 16:53:13,872 ERROR Exception on /employee/login [POST]
Traceback (most recent call last):
  File "C:\Users\itsvi\Desktop\Project1\venv\lib\site-packages\flask\app.py", line 2073, in wsgi_app
    response = self.full_dispatch_request()
  File "C:\Users\itsvi\Desktop\Project1\venv\lib\site-packages\flask\app.py", line 1518, in full_dispatch_request
    rv = self.handle_user_exception(e)
  File "C:\Users\itsvi\Desktop\Project1\venv\lib\site-packages\flask\app.py", line 1516, in full_dispatch_request
    rv = self.dispatch_request()
  File "C:\Users\itsvi\Desktop\Project1\venv\lib\site-packages\flask\app.py", line 1502, in dispatch_request
    return self.ensure_sync(self.view_functions[rule.endpoint])(**req.view_args)
  File "C:\Users\itsvi\Desktop\Project1\main.py", line 40, in service_get_login_for_employee
    employee_dictionary = return_employee.make_employee_dictionary()
AttributeError: 'NoneType' object has no attribute 'make_employee_dictionary'
2021-12-15 16:53:13,876 INFO 127.0.0.1 - - [15/Dec/2021 16:53:13] "[35m[1mPOST /employee/login HTTP/1.1[0m" 500 -
2021-12-15 16:53:17,787 ERROR Exception on /employee/login [POST]
Traceback (most recent call last):
  File "C:\Users\itsvi\Desktop\Project1\venv\lib\site-packages\flask\app.py", line 2073, in wsgi_app
    response = self.full_dispatch_request()
  File "C:\Users\itsvi\Desktop\Project1\venv\lib\site-packages\flask\app.py", line 1518, in full_dispatch_request
    rv = self.handle_user_exception(e)
  File "C:\Users\itsvi\Desktop\Project1\venv\lib\site-packages\flask\app.py", line 1516, in full_dispatch_request
    rv = self.dispatch_request()
  File "C:\Users\itsvi\Desktop\Project1\venv\lib\site-packages\flask\app.py", line 1502, in dispatch_request
    return self.ensure_sync(self.view_functions[rule.endpoint])(**req.view_args)
  File "C:\Users\itsvi\Desktop\Project1\main.py", line 40, in service_get_login_for_employee
    employee_dictionary = return_employee.make_employee_dictionary()
AttributeError: 'NoneType' object has no attribute 'make_employee_dictionary'
2021-12-15 16:53:17,788 INFO 127.0.0.1 - - [15/Dec/2021 16:53:17] "[35m[1mPOST /employee/login HTTP/1.1[0m" 500 -
2021-12-15 16:55:17,164 INFO  * Running on http://127.0.0.1:5000/ (Press CTRL+C to quit)
2021-12-15 16:55:20,915 ERROR Exception on /employee/login [POST]
Traceback (most recent call last):
  File "C:\Users\itsvi\Desktop\Project1\venv\lib\site-packages\flask\app.py", line 2073, in wsgi_app
    response = self.full_dispatch_request()
  File "C:\Users\itsvi\Desktop\Project1\venv\lib\site-packages\flask\app.py", line 1518, in full_dispatch_request
    rv = self.handle_user_exception(e)
  File "C:\Users\itsvi\Desktop\Project1\venv\lib\site-packages\flask\app.py", line 1516, in full_dispatch_request
    rv = self.dispatch_request()
  File "C:\Users\itsvi\Desktop\Project1\venv\lib\site-packages\flask\app.py", line 1502, in dispatch_request
    return self.ensure_sync(self.view_functions[rule.endpoint])(**req.view_args)
  File "C:\Users\itsvi\Desktop\Project1\main.py", line 40, in service_get_login_for_employee
    employee_dictionary = return_employee.make_employee_dictionary()
AttributeError: 'NoneType' object has no attribute 'make_employee_dictionary'
2021-12-15 16:55:20,918 INFO 127.0.0.1 - - [15/Dec/2021 16:55:20] "[35m[1mPOST /employee/login HTTP/1.1[0m" 500 -
2021-12-15 16:56:13,385 INFO  * Running on http://127.0.0.1:5000/ (Press CTRL+C to quit)
2021-12-15 16:56:39,310 ERROR Exception on /employee/login [POST]
Traceback (most recent call last):
  File "C:\Users\itsvi\Desktop\Project1\venv\lib\site-packages\flask\app.py", line 2073, in wsgi_app
    response = self.full_dispatch_request()
  File "C:\Users\itsvi\Desktop\Project1\venv\lib\site-packages\flask\app.py", line 1518, in full_dispatch_request
    rv = self.handle_user_exception(e)
  File "C:\Users\itsvi\Desktop\Project1\venv\lib\site-packages\flask\app.py", line 1516, in full_dispatch_request
    rv = self.dispatch_request()
  File "C:\Users\itsvi\Desktop\Project1\venv\lib\site-packages\flask\app.py", line 1502, in dispatch_request
    return self.ensure_sync(self.view_functions[rule.endpoint])(**req.view_args)
  File "C:\Users\itsvi\Desktop\Project1\main.py", line 40, in service_get_login_for_employee
    employee_dictionary = return_employee.make_employee_dictionary()
AttributeError: 'NoneType' object has no attribute 'make_employee_dictionary'
2021-12-15 16:56:39,313 INFO 127.0.0.1 - - [15/Dec/2021 16:56:39] "[35m[1mPOST /employee/login HTTP/1.1[0m" 500 -
2021-12-15 16:59:08,915 INFO  * Running on http://127.0.0.1:5000/ (Press CTRL+C to quit)
2021-12-15 16:59:11,200 ERROR Exception on /employee/login [POST]
Traceback (most recent call last):
  File "C:\Users\itsvi\Desktop\Project1\venv\lib\site-packages\flask\app.py", line 2073, in wsgi_app
    response = self.full_dispatch_request()
  File "C:\Users\itsvi\Desktop\Project1\venv\lib\site-packages\flask\app.py", line 1518, in full_dispatch_request
    rv = self.handle_user_exception(e)
  File "C:\Users\itsvi\Desktop\Project1\venv\lib\site-packages\flask\app.py", line 1516, in full_dispatch_request
    rv = self.dispatch_request()
  File "C:\Users\itsvi\Desktop\Project1\venv\lib\site-packages\flask\app.py", line 1502, in dispatch_request
    return self.ensure_sync(self.view_functions[rule.endpoint])(**req.view_args)
  File "C:\Users\itsvi\Desktop\Project1\main.py", line 40, in service_get_login_for_employee
    employee_dictionary = return_employee.make_employee_dictionary()
AttributeError: 'NoneType' object has no attribute 'make_employee_dictionary'
2021-12-15 16:59:11,202 INFO 127.0.0.1 - - [15/Dec/2021 16:59:11] "[35m[1mPOST /employee/login HTTP/1.1[0m" 500 -
2021-12-15 17:01:09,114 INFO  * Running on http://127.0.0.1:5000/ (Press CTRL+C to quit)
2021-12-15 17:01:10,824 ERROR Exception on /employee/login [POST]
Traceback (most recent call last):
  File "C:\Users\itsvi\Desktop\Project1\venv\lib\site-packages\flask\app.py", line 2073, in wsgi_app
    response = self.full_dispatch_request()
  File "C:\Users\itsvi\Desktop\Project1\venv\lib\site-packages\flask\app.py", line 1519, in full_dispatch_request
    return self.finalize_request(rv)
  File "C:\Users\itsvi\Desktop\Project1\venv\lib\site-packages\flask\app.py", line 1538, in finalize_request
    response = self.make_response(rv)
  File "C:\Users\itsvi\Desktop\Project1\venv\lib\site-packages\flask\app.py", line 1701, in make_response
    raise TypeError(
TypeError: The view function for 'service_get_login_for_employee' did not return a valid response. The function either returned None or ended without a return statement.
2021-12-15 17:01:10,827 INFO 127.0.0.1 - - [15/Dec/2021 17:01:10] "[35m[1mPOST /employee/login HTTP/1.1[0m" 500 -
2021-12-15 17:04:13,960 INFO  * Running on http://127.0.0.1:5000/ (Press CTRL+C to quit)
2021-12-15 17:04:16,960 INFO 127.0.0.1 - - [15/Dec/2021 17:04:16] "POST /employee/login HTTP/1.1" 200 -
2021-12-15 22:13:11,888 INFO  * Running on http://127.0.0.1:5000/ (Press CTRL+C to quit)
2021-12-15 22:13:18,860 INFO 127.0.0.1 - - [15/Dec/2021 22:13:18] "POST /employee/login HTTP/1.1" 200 -
2021-12-15 22:17:33,092 INFO  * Running on http://127.0.0.1:5000/ (Press CTRL+C to quit)
2021-12-15 22:17:39,801 ERROR Exception on /employees [GET]
Traceback (most recent call last):
  File "C:\Users\itsvi\Desktop\Project1\venv\lib\site-packages\flask\app.py", line 2073, in wsgi_app
    response = self.full_dispatch_request()
  File "C:\Users\itsvi\Desktop\Project1\venv\lib\site-packages\flask\app.py", line 1518, in full_dispatch_request
    rv = self.handle_user_exception(e)
  File "C:\Users\itsvi\Desktop\Project1\venv\lib\site-packages\flask\app.py", line 1516, in full_dispatch_request
    rv = self.dispatch_request()
  File "C:\Users\itsvi\Desktop\Project1\venv\lib\site-packages\flask\app.py", line 1502, in dispatch_request
    return self.ensure_sync(self.view_functions[rule.endpoint])(**req.view_args)
  File "C:\Users\itsvi\Desktop\Project1\main.py", line 19, in get_all_employees
    employees = employee_service.service_get_all_employees()
  File "C:\Users\itsvi\Desktop\Project1\service_layer\employee_postgres_service.py", line 14, in service_get_all_employees
    return self.employee_dao.get_all_employees()
TypeError: EmployeePostgresDAO.get_all_employees() missing 1 required positional argument: 'employee'
2021-12-15 22:17:39,852 INFO 127.0.0.1 - - [15/Dec/2021 22:17:39] "[35m[1mGET /employees HTTP/1.1[0m" 500 -
2021-12-15 22:18:03,828 INFO  * Running on http://127.0.0.1:5000/ (Press CTRL+C to quit)
2021-12-15 22:18:06,945 INFO 127.0.0.1 - - [15/Dec/2021 22:18:06] "GET /employees HTTP/1.1" 200 -
2021-12-15 22:18:25,819 INFO 127.0.0.1 - - [15/Dec/2021 22:18:25] "POST /employee/login HTTP/1.1" 200 -
2021-12-15 22:18:27,708 INFO 127.0.0.1 - - [15/Dec/2021 22:18:27] "POST /employee/login HTTP/1.1" 200 -
2021-12-15 22:18:28,702 INFO 127.0.0.1 - - [15/Dec/2021 22:18:28] "POST /employee/login HTTP/1.1" 200 -
2021-12-15 22:19:31,692 INFO  * Running on http://127.0.0.1:5000/ (Press CTRL+C to quit)
2021-12-15 22:30:43,108 INFO  * Running on http://127.0.0.1:5000/ (Press CTRL+C to quit)
2021-12-16 09:07:48,471 INFO  * Running on http://127.0.0.1:5000/ (Press CTRL+C to quit)
2021-12-16 09:12:05,283 INFO  * Running on http://127.0.0.1:5000/ (Press CTRL+C to quit)
2021-12-16 09:12:20,305 INFO 127.0.0.1 - - [16/Dec/2021 09:12:20] "POST /employee/login HTTP/1.1" 200 -
2021-12-16 09:18:59,673 INFO  * Running on http://127.0.0.1:5000/ (Press CTRL+C to quit)
2021-12-16 09:19:05,861 INFO 127.0.0.1 - - [16/Dec/2021 09:19:05] "POST /employee/login HTTP/1.1" 200 -
2021-12-16 09:19:12,462 INFO 127.0.0.1 - - [16/Dec/2021 09:19:12] "POST /employee/login HTTP/1.1" 200 -
2021-12-16 09:19:13,777 INFO 127.0.0.1 - - [16/Dec/2021 09:19:13] "POST /employee/login HTTP/1.1" 200 -
2021-12-16 09:21:19,386 INFO  * Running on http://127.0.0.1:5000/ (Press CTRL+C to quit)
2021-12-16 09:21:44,512 INFO  * Running on http://127.0.0.1:5000/ (Press CTRL+C to quit)
2021-12-16 09:21:50,825 INFO 127.0.0.1 - - [16/Dec/2021 09:21:50] "POST /employee/login HTTP/1.1" 200 -
2021-12-16 09:21:52,215 INFO 127.0.0.1 - - [16/Dec/2021 09:21:52] "POST /employee/login HTTP/1.1" 200 -
2021-12-16 09:23:12,750 INFO 127.0.0.1 - - [16/Dec/2021 09:23:12] "POST /employee/login HTTP/1.1" 200 -
2021-12-16 13:04:58,772 ERROR Exception on /employee/login [POST]
Traceback (most recent call last):
  File "C:\Users\itsvi\Desktop\Project1\venv\lib\site-packages\flask\app.py", line 2073, in wsgi_app
    response = self.full_dispatch_request()
  File "C:\Users\itsvi\Desktop\Project1\venv\lib\site-packages\flask\app.py", line 1518, in full_dispatch_request
    rv = self.handle_user_exception(e)
  File "C:\Users\itsvi\Desktop\Project1\venv\lib\site-packages\flask\app.py", line 1516, in full_dispatch_request
    rv = self.dispatch_request()
  File "C:\Users\itsvi\Desktop\Project1\venv\lib\site-packages\flask\app.py", line 1502, in dispatch_request
    return self.ensure_sync(self.view_functions[rule.endpoint])(**req.view_args)
  File "C:\Users\itsvi\Desktop\Project1\main.py", line 36, in service_get_login_for_employee
    return_employee: Employee = employee_service.service_get_login_for_employee(employee_id, employee_passcode)
  File "C:\Users\itsvi\Desktop\Project1\service_layer\employee_postgres_service.py", line 17, in service_get_login_for_employee
    employee_list = self.employee_dao.get_all_employees()
  File "C:\Users\itsvi\Desktop\Project1\service_layer\employee_postgres_dao.py", line 18, in get_all_employees
    cursor.execute(sql)
  File "C:\Users\itsvi\Desktop\Project1\venv\lib\site-packages\psycopg\cursor.py", line 561, in execute
    raise ex.with_traceback(None)
psycopg.OperationalError: sending query failed: server closed the connection unexpectedly
	This probably means the server terminated abnormally
	before or while processing the request.
server closed the connection unexpectedly
	This probably means the server terminated abnormally
	before or while processing the request.
2021-12-16 13:04:58,861 INFO 127.0.0.1 - - [16/Dec/2021 13:04:58] "[35m[1mPOST /employee/login HTTP/1.1[0m" 500 -
2021-12-16 13:07:53,336 INFO  * Running on http://127.0.0.1:5000/ (Press CTRL+C to quit)
2021-12-16 13:07:53,819 INFO 127.0.0.1 - - [16/Dec/2021 13:07:53] "POST /employee/login HTTP/1.1" 200 -
2021-12-16 13:11:38,369 INFO 127.0.0.1 - - [16/Dec/2021 13:11:38] "POST /employee/login HTTP/1.1" 200 -
2021-12-16 13:16:08,349 INFO  * Running on http://127.0.0.1:5000/ (Press CTRL+C to quit)
2021-12-16 13:16:13,227 DEBUG  firstName: Victor, lastName: Victor, employeeId: 1, passcode: mycode 
2021-12-16 13:16:13,228 INFO 127.0.0.1 - - [16/Dec/2021 13:16:13] "POST /employee/login HTTP/1.1" 200 -
2021-12-16 13:28:54,452 DEBUG  firstName: Victor, lastName: Victor, employeeId: 1, passcode: mycode 
2021-12-16 13:28:54,453 INFO 127.0.0.1 - - [16/Dec/2021 13:28:54] "POST /employee/login HTTP/1.1" 200 -
2021-12-16 15:44:00,700 INFO  * Running on http://127.0.0.1:5000/ (Press CTRL+C to quit)
2021-12-17 11:19:29,610 INFO  * Running on http://127.0.0.1:5000/ (Press CTRL+C to quit)
2021-12-17 11:46:17,967 INFO  * Running on http://127.0.0.1:5000/ (Press CTRL+C to quit)
2021-12-19 17:45:23,394 INFO  * Running on http://127.0.0.1:5000/ (Press CTRL+C to quit)
2021-12-19 18:40:44,660 INFO  * Running on http://127.0.0.1:5000/ (Press CTRL+C to quit)
2021-12-19 18:41:02,235 INFO 127.0.0.1 - - [19/Dec/2021 18:41:02] "GET /employees HTTP/1.1" 200 -
2021-12-19 18:41:06,435 DEBUG  firstName: Victor, lastName: Victor, employeeId: 1, passcode: mycode 
2021-12-19 18:41:06,436 INFO 127.0.0.1 - - [19/Dec/2021 18:41:06] "POST /employee/login HTTP/1.1" 200 -
2021-12-21 17:00:19,912 INFO  * Running on http://127.0.0.1:5000/ (Press CTRL+C to quit)
2021-12-21 17:00:51,696 INFO 127.0.0.1 - - [21/Dec/2021 17:00:51] "GET /employees HTTP/1.1" 200 -
2021-12-21 17:00:56,127 DEBUG  firstName: Victor, lastName: Victor, employeeId: 1, passcode: mycode 
2021-12-21 17:00:56,128 INFO 127.0.0.1 - - [21/Dec/2021 17:00:56] "POST /employee/login HTTP/1.1" 200 -
2021-12-21 17:13:14,666 INFO  * Running on http://127.0.0.1:5000/ (Press CTRL+C to quit)
2021-12-21 17:14:06,481 INFO 127.0.0.1 - - [21/Dec/2021 17:14:06] "[33mGET /mangers HTTP/1.1[0m" 404 -
2021-12-21 17:14:19,797 INFO 127.0.0.1 - - [21/Dec/2021 17:14:19] "GET /managers HTTP/1.1" 200 -
2021-12-21 17:19:28,712 INFO  * Running on http://127.0.0.1:5000/ (Press CTRL+C to quit)
2021-12-21 17:21:26,027 ERROR Exception on /employee/login [POST]
Traceback (most recent call last):
  File "C:\Users\itsvi\Desktop\Project1\venv\lib\site-packages\flask\app.py", line 2073, in wsgi_app
    response = self.full_dispatch_request()
  File "C:\Users\itsvi\Desktop\Project1\venv\lib\site-packages\flask\app.py", line 1518, in full_dispatch_request
    rv = self.handle_user_exception(e)
  File "C:\Users\itsvi\Desktop\Project1\venv\lib\site-packages\flask\app.py", line 1516, in full_dispatch_request
    rv = self.dispatch_request()
  File "C:\Users\itsvi\Desktop\Project1\venv\lib\site-packages\flask\app.py", line 1502, in dispatch_request
    return self.ensure_sync(self.view_functions[rule.endpoint])(**req.view_args)
  File "C:\Users\itsvi\Desktop\Project1\main.py", line 43, in service_get_login_for_employee
    employee_id = result["employeeId"]
KeyError: 'employeeId'
2021-12-21 17:21:26,049 INFO 127.0.0.1 - - [21/Dec/2021 17:21:26] "[35m[1mPOST /employee/login HTTP/1.1[0m" 500 -
2021-12-21 17:22:19,615 DEBUG  firstName: Vic, lastName: Vic, managerId: 1, passcode: mycode 
2021-12-21 17:22:19,616 INFO 127.0.0.1 - - [21/Dec/2021 17:22:19] "POST /manager/login HTTP/1.1" 200 -
2021-12-22 06:53:18,674 INFO  * Running on http://127.0.0.1:5000/ (Press CTRL+C to quit)
2021-12-22 06:53:23,959 INFO  * Running on http://127.0.0.1:5000/ (Press CTRL+C to quit)
2021-12-22 07:04:00,844 INFO  * Running on http://127.0.0.1:5000/ (Press CTRL+C to quit)
2021-12-22 07:08:26,764 INFO  * Running on http://127.0.0.1:5000/ (Press CTRL+C to quit)
2021-12-22 09:37:48,171 INFO  * Running on http://127.0.0.1:5000/ (Press CTRL+C to quit)
2021-12-22 09:38:17,962 INFO  * Running on http://127.0.0.1:5000/ (Press CTRL+C to quit)
2021-12-22 09:38:34,424 INFO 127.0.0.1 - - [22/Dec/2021 09:38:34] "GET /employees HTTP/1.1" 200 -
2021-12-22 09:38:38,247 INFO 127.0.0.1 - - [22/Dec/2021 09:38:38] "POST /employee/login HTTP/1.1" 200 -
2021-12-22 09:38:55,858 DEBUG  firstName: Flores, lastName: Flores, employeeId: 2, passcode: mycode2 
2021-12-22 09:38:55,858 INFO 127.0.0.1 - - [22/Dec/2021 09:38:55] "POST /employee/login HTTP/1.1" 200 -
2021-12-22 09:39:03,605 INFO 127.0.0.1 - - [22/Dec/2021 09:39:03] "POST /employee/login HTTP/1.1" 200 -
2021-12-22 09:39:25,562 DEBUG  firstName: Herrera, lastName: Herrera, employeeId: 3, passcode: mycode3 
2021-12-22 09:39:25,563 INFO 127.0.0.1 - - [22/Dec/2021 09:39:25] "POST /employee/login HTTP/1.1" 200 -
2021-12-22 09:39:32,841 DEBUG  firstName: Vic, lastName: Vic, managerId: 1, passcode: mycode 
2021-12-22 09:39:32,841 INFO 127.0.0.1 - - [22/Dec/2021 09:39:32] "POST /manager/login HTTP/1.1" 200 -
2021-12-22 09:39:44,381 DEBUG  firstName: Flo, lastName: Flo, managerId: 2, passcode: mycode2 
2021-12-22 09:39:44,382 INFO 127.0.0.1 - - [22/Dec/2021 09:39:44] "POST /manager/login HTTP/1.1" 200 -
2021-12-22 09:39:51,080 INFO 127.0.0.1 - - [22/Dec/2021 09:39:51] "GET /managers HTTP/1.1" 200 -
2021-12-22 09:56:53,221 DEBUG  firstName: Herrera, lastName: Herrera, employeeId: 3, passcode: mycode3 
2021-12-22 09:56:53,221 INFO 127.0.0.1 - - [22/Dec/2021 09:56:53] "POST /employee/login HTTP/1.1" 200 -
2021-12-22 09:57:01,045 INFO 127.0.0.1 - - [22/Dec/2021 09:57:01] "POST /employee/login HTTP/1.1" 200 -
2021-12-22 13:11:55,395 INFO  * Running on http://127.0.0.1:5000/ (Press CTRL+C to quit)
2021-12-22 13:13:08,434 INFO 127.0.0.1 - - [22/Dec/2021 13:13:08] "GET /employee/2 HTTP/1.1" 200 -
2021-12-22 13:13:17,181 INFO 127.0.0.1 - - [22/Dec/2021 13:13:17] "GET /employee/1 HTTP/1.1" 200 -
2021-12-22 13:14:01,511 INFO 127.0.0.1 - - [22/Dec/2021 13:14:01] "GET /employee/9 HTTP/1.1" 200 -
2021-12-22 13:14:28,530 INFO 127.0.0.1 - - [22/Dec/2021 13:14:28] "GET /employee/5 HTTP/1.1" 200 -
2021-12-22 13:14:32,715 INFO 127.0.0.1 - - [22/Dec/2021 13:14:32] "GET /employee/3 HTTP/1.1" 200 -
2021-12-22 13:14:40,684 INFO 127.0.0.1 - - [22/Dec/2021 13:14:40] "GET /employee/1 HTTP/1.1" 200 -
2021-12-22 13:14:47,153 INFO 127.0.0.1 - - [22/Dec/2021 13:14:47] "GET /employee/2 HTTP/1.1" 200 -
2021-12-22 13:16:42,223 INFO  * Running on http://127.0.0.1:5000/ (Press CTRL+C to quit)
2021-12-22 13:16:46,552 INFO 127.0.0.1 - - [22/Dec/2021 13:16:46] "[33mGET /employees HTTP/1.1[0m" 404 -
2021-12-22 13:16:53,414 INFO 127.0.0.1 - - [22/Dec/2021 13:16:53] "GET /employee HTTP/1.1" 200 -
2021-12-22 13:17:45,821 INFO 127.0.0.1 - - [22/Dec/2021 13:17:45] "POST /employee/login HTTP/1.1" 200 -
2021-12-22 13:18:09,777 DEBUG  firstName: Vic, lastName: Vic, employeeId: 5, passcode: mycode 
2021-12-22 13:18:09,778 INFO 127.0.0.1 - - [22/Dec/2021 13:18:09] "POST /employee/login HTTP/1.1" 200 -
2021-12-22 13:39:30,183 INFO  * Running on http://127.0.0.1:5000/ (Press CTRL+C to quit)
2021-12-22 13:39:33,270 INFO 127.0.0.1 - - [22/Dec/2021 13:39:33] "GET /employee/reimbursement/3 HTTP/1.1" 200 -
2021-12-22 13:42:49,963 ERROR Exception on /employee/reimbursement/7 [GET]
Traceback (most recent call last):
  File "C:\Users\itsvi\Desktop\Project1\venv\lib\site-packages\flask\app.py", line 2073, in wsgi_app
    response = self.full_dispatch_request()
  File "C:\Users\itsvi\Desktop\Project1\venv\lib\site-packages\flask\app.py", line 1518, in full_dispatch_request
    rv = self.handle_user_exception(e)
  File "C:\Users\itsvi\Desktop\Project1\venv\lib\site-packages\flask\app.py", line 1516, in full_dispatch_request
    rv = self.dispatch_request()
  File "C:\Users\itsvi\Desktop\Project1\venv\lib\site-packages\flask\app.py", line 1502, in dispatch_request
    return self.ensure_sync(self.view_functions[rule.endpoint])(**req.view_args)
  File "C:\Users\itsvi\Desktop\Project1\main.py", line 83, in get_employee_reimbursement_by_employee_id
    reimbursement_as_reimbursement = reimbursement_service.service_select_reimbursement_by_employee_id(int(employee_id))
  File "C:\Users\itsvi\Desktop\Project1\service_layer\service_imp\reimbursement_postgres_service.py", line 48, in service_select_reimbursement_by_employee_id
    raise EmployeeNonexistException("Does not exist.")
custom_exceptions.employee_nonexist_exception.EmployeeNonexistException: Does not exist.
2021-12-22 13:42:49,994 INFO 127.0.0.1 - - [22/Dec/2021 13:42:49] "[35m[1mGET /employee/reimbursement/7 HTTP/1.1[0m" 500 -
2021-12-22 13:42:58,009 ERROR Exception on /employee/reimbursement/6 [GET]
Traceback (most recent call last):
  File "C:\Users\itsvi\Desktop\Project1\venv\lib\site-packages\flask\app.py", line 2073, in wsgi_app
    response = self.full_dispatch_request()
  File "C:\Users\itsvi\Desktop\Project1\venv\lib\site-packages\flask\app.py", line 1518, in full_dispatch_request
    rv = self.handle_user_exception(e)
  File "C:\Users\itsvi\Desktop\Project1\venv\lib\site-packages\flask\app.py", line 1516, in full_dispatch_request
    rv = self.dispatch_request()
  File "C:\Users\itsvi\Desktop\Project1\venv\lib\site-packages\flask\app.py", line 1502, in dispatch_request
    return self.ensure_sync(self.view_functions[rule.endpoint])(**req.view_args)
  File "C:\Users\itsvi\Desktop\Project1\main.py", line 83, in get_employee_reimbursement_by_employee_id
    reimbursement_as_reimbursement = reimbursement_service.service_select_reimbursement_by_employee_id(int(employee_id))
  File "C:\Users\itsvi\Desktop\Project1\service_layer\service_imp\reimbursement_postgres_service.py", line 48, in service_select_reimbursement_by_employee_id
    raise EmployeeNonexistException("Does not exist.")
custom_exceptions.employee_nonexist_exception.EmployeeNonexistException: Does not exist.
2021-12-22 13:42:58,010 INFO 127.0.0.1 - - [22/Dec/2021 13:42:58] "[35m[1mGET /employee/reimbursement/6 HTTP/1.1[0m" 500 -
2021-12-22 13:43:01,812 ERROR Exception on /employee/reimbursement/5 [GET]
Traceback (most recent call last):
  File "C:\Users\itsvi\Desktop\Project1\venv\lib\site-packages\flask\app.py", line 2073, in wsgi_app
    response = self.full_dispatch_request()
  File "C:\Users\itsvi\Desktop\Project1\venv\lib\site-packages\flask\app.py", line 1518, in full_dispatch_request
    rv = self.handle_user_exception(e)
  File "C:\Users\itsvi\Desktop\Project1\venv\lib\site-packages\flask\app.py", line 1516, in full_dispatch_request
    rv = self.dispatch_request()
  File "C:\Users\itsvi\Desktop\Project1\venv\lib\site-packages\flask\app.py", line 1502, in dispatch_request
    return self.ensure_sync(self.view_functions[rule.endpoint])(**req.view_args)
  File "C:\Users\itsvi\Desktop\Project1\main.py", line 83, in get_employee_reimbursement_by_employee_id
    reimbursement_as_reimbursement = reimbursement_service.service_select_reimbursement_by_employee_id(int(employee_id))
  File "C:\Users\itsvi\Desktop\Project1\service_layer\service_imp\reimbursement_postgres_service.py", line 48, in service_select_reimbursement_by_employee_id
    raise EmployeeNonexistException("Does not exist.")
custom_exceptions.employee_nonexist_exception.EmployeeNonexistException: Does not exist.
2021-12-22 13:43:01,813 INFO 127.0.0.1 - - [22/Dec/2021 13:43:01] "[35m[1mGET /employee/reimbursement/5 HTTP/1.1[0m" 500 -
2021-12-22 13:43:06,322 ERROR Exception on /employee/reimbursement/4 [GET]
Traceback (most recent call last):
  File "C:\Users\itsvi\Desktop\Project1\venv\lib\site-packages\flask\app.py", line 2073, in wsgi_app
    response = self.full_dispatch_request()
  File "C:\Users\itsvi\Desktop\Project1\venv\lib\site-packages\flask\app.py", line 1518, in full_dispatch_request
    rv = self.handle_user_exception(e)
  File "C:\Users\itsvi\Desktop\Project1\venv\lib\site-packages\flask\app.py", line 1516, in full_dispatch_request
    rv = self.dispatch_request()
  File "C:\Users\itsvi\Desktop\Project1\venv\lib\site-packages\flask\app.py", line 1502, in dispatch_request
    return self.ensure_sync(self.view_functions[rule.endpoint])(**req.view_args)
  File "C:\Users\itsvi\Desktop\Project1\main.py", line 83, in get_employee_reimbursement_by_employee_id
    reimbursement_as_reimbursement = reimbursement_service.service_select_reimbursement_by_employee_id(int(employee_id))
  File "C:\Users\itsvi\Desktop\Project1\service_layer\service_imp\reimbursement_postgres_service.py", line 48, in service_select_reimbursement_by_employee_id
    raise EmployeeNonexistException("Does not exist.")
custom_exceptions.employee_nonexist_exception.EmployeeNonexistException: Does not exist.
2021-12-22 13:43:06,324 INFO 127.0.0.1 - - [22/Dec/2021 13:43:06] "[35m[1mGET /employee/reimbursement/4 HTTP/1.1[0m" 500 -
2021-12-22 13:43:15,322 INFO 127.0.0.1 - - [22/Dec/2021 13:43:15] "GET /employee/reimbursement/2 HTTP/1.1" 200 -
2021-12-22 14:20:43,516 INFO  * Running on http://127.0.0.1:5000/ (Press CTRL+C to quit)
2021-12-22 14:20:45,214 ERROR Exception on /reimbursement [POST]
Traceback (most recent call last):
  File "C:\Users\itsvi\Desktop\Project1\venv\lib\site-packages\flask\app.py", line 2073, in wsgi_app
    response = self.full_dispatch_request()
  File "C:\Users\itsvi\Desktop\Project1\venv\lib\site-packages\flask\app.py", line 1518, in full_dispatch_request
    rv = self.handle_user_exception(e)
  File "C:\Users\itsvi\Desktop\Project1\venv\lib\site-packages\flask\app.py", line 1516, in full_dispatch_request
    rv = self.dispatch_request()
  File "C:\Users\itsvi\Desktop\Project1\venv\lib\site-packages\flask\app.py", line 1502, in dispatch_request
    return self.ensure_sync(self.view_functions[rule.endpoint])(**req.view_args)
  File "C:\Users\itsvi\Desktop\Project1\main.py", line 106, in service_create_reimbursement
    reimbursement_to_return = reimbursement_service.service_create_get_reimbursement(new_reimbursement)
  File "C:\Users\itsvi\Desktop\Project1\service_layer\service_imp\reimbursement_postgres_service.py", line 31, in service_create_get_reimbursement
    raise InvalidAcceptanceException("Invalid acceptance.")
custom_exceptions.invalid_acceptance_exception.InvalidAcceptanceException: Invalid acceptance.
2021-12-22 14:20:45,254 INFO 127.0.0.1 - - [22/Dec/2021 14:20:45] "[35m[1mPOST /reimbursement HTTP/1.1[0m" 500 -
2021-12-22 14:21:52,931 INFO 127.0.0.1 - - [22/Dec/2021 14:21:52] "POST /reimbursement HTTP/1.1" 200 -
2021-12-22 14:23:11,770 INFO 127.0.0.1 - - [22/Dec/2021 14:23:11] "[31m[1mPOST /reimbursement HTTP/1.1[0m" 400 -
2021-12-22 14:23:30,145 INFO 127.0.0.1 - - [22/Dec/2021 14:23:30] "POST /reimbursement HTTP/1.1" 200 -
2021-12-22 14:27:25,361 INFO 127.0.0.1 - - [22/Dec/2021 14:27:25] "[33mGET /reimbursement/all HTTP/1.1[0m" 404 -
2021-12-22 14:27:36,026 INFO  * Running on http://127.0.0.1:5000/ (Press CTRL+C to quit)
2021-12-22 14:27:45,476 INFO 127.0.0.1 - - [22/Dec/2021 14:27:45] "GET /reimbursement/all HTTP/1.1" 200 -
2021-12-22 14:29:56,564 INFO  * Running on http://127.0.0.1:5000/ (Press CTRL+C to quit)
2021-12-22 14:30:11,969 ERROR Exception on /past/reimbursements/3 [GET]
Traceback (most recent call last):
  File "C:\Users\itsvi\Desktop\Project1\venv\lib\site-packages\flask\app.py", line 2073, in wsgi_app
    response = self.full_dispatch_request()
  File "C:\Users\itsvi\Desktop\Project1\venv\lib\site-packages\flask\app.py", line 1518, in full_dispatch_request
    rv = self.handle_user_exception(e)
  File "C:\Users\itsvi\Desktop\Project1\venv\lib\site-packages\flask\app.py", line 1516, in full_dispatch_request
    rv = self.dispatch_request()
  File "C:\Users\itsvi\Desktop\Project1\venv\lib\site-packages\flask\app.py", line 1502, in dispatch_request
    return self.ensure_sync(self.view_functions[rule.endpoint])(**req.view_args)
  File "C:\Users\itsvi\Desktop\Project1\main.py", line 132, in get_all_past_reimbursement_information
    reimbursement_as_reimbursement = reimbursement_service.service_get_past_reimbursements_by_manager_id(
AttributeError: 'ReimbursementPostgresService' object has no attribute 'service_get_past_reimbursements_by_manager_id'
2021-12-22 14:30:11,971 INFO 127.0.0.1 - - [22/Dec/2021 14:30:11] "[35m[1mGET /past/reimbursements/3 HTTP/1.1[0m" 500 -
2021-12-22 14:31:03,092 ERROR Exception on /past/reimbursements/2 [GET]
Traceback (most recent call last):
  File "C:\Users\itsvi\Desktop\Project1\venv\lib\site-packages\flask\app.py", line 2073, in wsgi_app
    response = self.full_dispatch_request()
  File "C:\Users\itsvi\Desktop\Project1\venv\lib\site-packages\flask\app.py", line 1518, in full_dispatch_request
    rv = self.handle_user_exception(e)
  File "C:\Users\itsvi\Desktop\Project1\venv\lib\site-packages\flask\app.py", line 1516, in full_dispatch_request
    rv = self.dispatch_request()
  File "C:\Users\itsvi\Desktop\Project1\venv\lib\site-packages\flask\app.py", line 1502, in dispatch_request
    return self.ensure_sync(self.view_functions[rule.endpoint])(**req.view_args)
  File "C:\Users\itsvi\Desktop\Project1\main.py", line 132, in get_all_past_reimbursement_information
    reimbursement_as_reimbursement = reimbursement_service.service_get_past_reimbursements_by_manager_id(
AttributeError: 'ReimbursementPostgresService' object has no attribute 'service_get_past_reimbursements_by_manager_id'
2021-12-22 14:31:03,093 INFO 127.0.0.1 - - [22/Dec/2021 14:31:03] "[35m[1mGET /past/reimbursements/2 HTTP/1.1[0m" 500 -
2021-12-22 14:31:06,120 ERROR Exception on /past/reimbursements/1 [GET]
Traceback (most recent call last):
  File "C:\Users\itsvi\Desktop\Project1\venv\lib\site-packages\flask\app.py", line 2073, in wsgi_app
    response = self.full_dispatch_request()
  File "C:\Users\itsvi\Desktop\Project1\venv\lib\site-packages\flask\app.py", line 1518, in full_dispatch_request
    rv = self.handle_user_exception(e)
  File "C:\Users\itsvi\Desktop\Project1\venv\lib\site-packages\flask\app.py", line 1516, in full_dispatch_request
    rv = self.dispatch_request()
  File "C:\Users\itsvi\Desktop\Project1\venv\lib\site-packages\flask\app.py", line 1502, in dispatch_request
    return self.ensure_sync(self.view_functions[rule.endpoint])(**req.view_args)
  File "C:\Users\itsvi\Desktop\Project1\main.py", line 132, in get_all_past_reimbursement_information
    reimbursement_as_reimbursement = reimbursement_service.service_get_past_reimbursements_by_manager_id(
AttributeError: 'ReimbursementPostgresService' object has no attribute 'service_get_past_reimbursements_by_manager_id'
2021-12-22 14:31:06,121 INFO 127.0.0.1 - - [22/Dec/2021 14:31:06] "[35m[1mGET /past/reimbursements/1 HTTP/1.1[0m" 500 -
2021-12-22 14:32:50,587 ERROR Exception on /past/reimbursements/3 [GET]
Traceback (most recent call last):
  File "C:\Users\itsvi\Desktop\Project1\venv\lib\site-packages\flask\app.py", line 2073, in wsgi_app
    response = self.full_dispatch_request()
  File "C:\Users\itsvi\Desktop\Project1\venv\lib\site-packages\flask\app.py", line 1518, in full_dispatch_request
    rv = self.handle_user_exception(e)
  File "C:\Users\itsvi\Desktop\Project1\venv\lib\site-packages\flask\app.py", line 1516, in full_dispatch_request
    rv = self.dispatch_request()
  File "C:\Users\itsvi\Desktop\Project1\venv\lib\site-packages\flask\app.py", line 1502, in dispatch_request
    return self.ensure_sync(self.view_functions[rule.endpoint])(**req.view_args)
  File "C:\Users\itsvi\Desktop\Project1\main.py", line 132, in get_all_past_reimbursement_information
    reimbursement_as_reimbursement = reimbursement_service.service_get_past_reimbursements_by_manager_id(
AttributeError: 'ReimbursementPostgresService' object has no attribute 'service_get_past_reimbursements_by_manager_id'
2021-12-22 14:32:50,588 INFO 127.0.0.1 - - [22/Dec/2021 14:32:50] "[35m[1mGET /past/reimbursements/3 HTTP/1.1[0m" 500 -
2021-12-22 14:34:17,499 INFO  * Running on http://127.0.0.1:5000/ (Press CTRL+C to quit)
2021-12-22 14:34:38,686 ERROR Exception on /past/reimbursements/10 [GET]
Traceback (most recent call last):
  File "C:\Users\itsvi\Desktop\Project1\venv\lib\site-packages\flask\app.py", line 2073, in wsgi_app
    response = self.full_dispatch_request()
  File "C:\Users\itsvi\Desktop\Project1\venv\lib\site-packages\flask\app.py", line 1518, in full_dispatch_request
    rv = self.handle_user_exception(e)
  File "C:\Users\itsvi\Desktop\Project1\venv\lib\site-packages\flask\app.py", line 1516, in full_dispatch_request
    rv = self.dispatch_request()
  File "C:\Users\itsvi\Desktop\Project1\venv\lib\site-packages\flask\app.py", line 1502, in dispatch_request
    return self.ensure_sync(self.view_functions[rule.endpoint])(**req.view_args)
  File "C:\Users\itsvi\Desktop\Project1\main.py", line 132, in get_all_past_reimbursement_information
    reimbursement_as_reimbursement = reimbursement_service.service_get_past_reimbursements_by_manager_id(int(manager_id))
AttributeError: 'ReimbursementPostgresService' object has no attribute 'service_get_past_reimbursements_by_manager_id'
2021-12-22 14:34:38,690 INFO 127.0.0.1 - - [22/Dec/2021 14:34:38] "[35m[1mGET /past/reimbursements/10 HTTP/1.1[0m" 500 -
2021-12-22 14:34:43,847 ERROR Exception on /past/reimbursements/20 [GET]
Traceback (most recent call last):
  File "C:\Users\itsvi\Desktop\Project1\venv\lib\site-packages\flask\app.py", line 2073, in wsgi_app
    response = self.full_dispatch_request()
  File "C:\Users\itsvi\Desktop\Project1\venv\lib\site-packages\flask\app.py", line 1518, in full_dispatch_request
    rv = self.handle_user_exception(e)
  File "C:\Users\itsvi\Desktop\Project1\venv\lib\site-packages\flask\app.py", line 1516, in full_dispatch_request
    rv = self.dispatch_request()
  File "C:\Users\itsvi\Desktop\Project1\venv\lib\site-packages\flask\app.py", line 1502, in dispatch_request
    return self.ensure_sync(self.view_functions[rule.endpoint])(**req.view_args)
  File "C:\Users\itsvi\Desktop\Project1\main.py", line 132, in get_all_past_reimbursement_information
    reimbursement_as_reimbursement = reimbursement_service.service_get_past_reimbursements_by_manager_id(int(manager_id))
AttributeError: 'ReimbursementPostgresService' object has no attribute 'service_get_past_reimbursements_by_manager_id'
2021-12-22 14:34:43,848 INFO 127.0.0.1 - - [22/Dec/2021 14:34:43] "[35m[1mGET /past/reimbursements/20 HTTP/1.1[0m" 500 -
2021-12-22 14:34:47,701 ERROR Exception on /past/reimbursements/2 [GET]
Traceback (most recent call last):
  File "C:\Users\itsvi\Desktop\Project1\venv\lib\site-packages\flask\app.py", line 2073, in wsgi_app
    response = self.full_dispatch_request()
  File "C:\Users\itsvi\Desktop\Project1\venv\lib\site-packages\flask\app.py", line 1518, in full_dispatch_request
    rv = self.handle_user_exception(e)
  File "C:\Users\itsvi\Desktop\Project1\venv\lib\site-packages\flask\app.py", line 1516, in full_dispatch_request
    rv = self.dispatch_request()
  File "C:\Users\itsvi\Desktop\Project1\venv\lib\site-packages\flask\app.py", line 1502, in dispatch_request
    return self.ensure_sync(self.view_functions[rule.endpoint])(**req.view_args)
  File "C:\Users\itsvi\Desktop\Project1\main.py", line 132, in get_all_past_reimbursement_information
    reimbursement_as_reimbursement = reimbursement_service.service_get_past_reimbursements_by_manager_id(int(manager_id))
AttributeError: 'ReimbursementPostgresService' object has no attribute 'service_get_past_reimbursements_by_manager_id'
2021-12-22 14:34:47,702 INFO 127.0.0.1 - - [22/Dec/2021 14:34:47] "[35m[1mGET /past/reimbursements/2 HTTP/1.1[0m" 500 -
2021-12-22 15:16:46,430 INFO  * Running on http://127.0.0.1:5000/ (Press CTRL+C to quit)
2021-12-22 15:20:44,693 INFO 127.0.0.1 - - [22/Dec/2021 15:20:44] "[33mGET /manager/pending/reimbursements/2 HTTP/1.1[0m" 404 -
2021-12-22 15:20:59,383 ERROR Exception on /manager/pending/reimbursement/2 [GET]
Traceback (most recent call last):
  File "C:\Users\itsvi\Desktop\Project1\venv\lib\site-packages\flask\app.py", line 2073, in wsgi_app
    response = self.full_dispatch_request()
  File "C:\Users\itsvi\Desktop\Project1\venv\lib\site-packages\flask\app.py", line 1518, in full_dispatch_request
    rv = self.handle_user_exception(e)
  File "C:\Users\itsvi\Desktop\Project1\venv\lib\site-packages\flask\app.py", line 1516, in full_dispatch_request
    rv = self.dispatch_request()
  File "C:\Users\itsvi\Desktop\Project1\venv\lib\site-packages\flask\app.py", line 1502, in dispatch_request
    return self.ensure_sync(self.view_functions[rule.endpoint])(**req.view_args)
  File "C:\Users\itsvi\Desktop\Project1\main.py", line 143, in get_all_pending_reimbursement_by_manager_id
    reimbursement_as_reimbursement = reimbursement_service.service_get_all_pending_reimbursements_by_manager_id(
AttributeError: 'ReimbursementPostgresService' object has no attribute 'service_get_all_pending_reimbursements_by_manager_id'
2021-12-22 15:20:59,386 INFO 127.0.0.1 - - [22/Dec/2021 15:20:59] "[35m[1mGET /manager/pending/reimbursement/2 HTTP/1.1[0m" 500 -
2021-12-22 15:21:02,147 ERROR Exception on /manager/pending/reimbursement/2 [GET]
Traceback (most recent call last):
  File "C:\Users\itsvi\Desktop\Project1\venv\lib\site-packages\flask\app.py", line 2073, in wsgi_app
    response = self.full_dispatch_request()
  File "C:\Users\itsvi\Desktop\Project1\venv\lib\site-packages\flask\app.py", line 1518, in full_dispatch_request
    rv = self.handle_user_exception(e)
  File "C:\Users\itsvi\Desktop\Project1\venv\lib\site-packages\flask\app.py", line 1516, in full_dispatch_request
    rv = self.dispatch_request()
  File "C:\Users\itsvi\Desktop\Project1\venv\lib\site-packages\flask\app.py", line 1502, in dispatch_request
    return self.ensure_sync(self.view_functions[rule.endpoint])(**req.view_args)
  File "C:\Users\itsvi\Desktop\Project1\main.py", line 143, in get_all_pending_reimbursement_by_manager_id
    reimbursement_as_reimbursement = reimbursement_service.service_get_all_pending_reimbursements_by_manager_id(
AttributeError: 'ReimbursementPostgresService' object has no attribute 'service_get_all_pending_reimbursements_by_manager_id'
2021-12-22 15:21:02,149 INFO 127.0.0.1 - - [22/Dec/2021 15:21:02] "[35m[1mGET /manager/pending/reimbursement/2 HTTP/1.1[0m" 500 -
2021-12-22 15:21:05,283 ERROR Exception on /manager/pending/reimbursement/3 [GET]
Traceback (most recent call last):
  File "C:\Users\itsvi\Desktop\Project1\venv\lib\site-packages\flask\app.py", line 2073, in wsgi_app
    response = self.full_dispatch_request()
  File "C:\Users\itsvi\Desktop\Project1\venv\lib\site-packages\flask\app.py", line 1518, in full_dispatch_request
    rv = self.handle_user_exception(e)
  File "C:\Users\itsvi\Desktop\Project1\venv\lib\site-packages\flask\app.py", line 1516, in full_dispatch_request
    rv = self.dispatch_request()
  File "C:\Users\itsvi\Desktop\Project1\venv\lib\site-packages\flask\app.py", line 1502, in dispatch_request
    return self.ensure_sync(self.view_functions[rule.endpoint])(**req.view_args)
  File "C:\Users\itsvi\Desktop\Project1\main.py", line 143, in get_all_pending_reimbursement_by_manager_id
    reimbursement_as_reimbursement = reimbursement_service.service_get_all_pending_reimbursements_by_manager_id(
AttributeError: 'ReimbursementPostgresService' object has no attribute 'service_get_all_pending_reimbursements_by_manager_id'
2021-12-22 15:21:05,284 INFO 127.0.0.1 - - [22/Dec/2021 15:21:05] "[35m[1mGET /manager/pending/reimbursement/3 HTTP/1.1[0m" 500 -
2021-12-22 15:21:08,190 ERROR Exception on /manager/pending/reimbursement/1 [GET]
Traceback (most recent call last):
  File "C:\Users\itsvi\Desktop\Project1\venv\lib\site-packages\flask\app.py", line 2073, in wsgi_app
    response = self.full_dispatch_request()
  File "C:\Users\itsvi\Desktop\Project1\venv\lib\site-packages\flask\app.py", line 1518, in full_dispatch_request
    rv = self.handle_user_exception(e)
  File "C:\Users\itsvi\Desktop\Project1\venv\lib\site-packages\flask\app.py", line 1516, in full_dispatch_request
    rv = self.dispatch_request()
  File "C:\Users\itsvi\Desktop\Project1\venv\lib\site-packages\flask\app.py", line 1502, in dispatch_request
    return self.ensure_sync(self.view_functions[rule.endpoint])(**req.view_args)
  File "C:\Users\itsvi\Desktop\Project1\main.py", line 143, in get_all_pending_reimbursement_by_manager_id
    reimbursement_as_reimbursement = reimbursement_service.service_get_all_pending_reimbursements_by_manager_id(
AttributeError: 'ReimbursementPostgresService' object has no attribute 'service_get_all_pending_reimbursements_by_manager_id'
2021-12-22 15:21:08,192 INFO 127.0.0.1 - - [22/Dec/2021 15:21:08] "[35m[1mGET /manager/pending/reimbursement/1 HTTP/1.1[0m" 500 -
2021-12-22 15:21:11,821 INFO  * Running on http://127.0.0.1:5000/ (Press CTRL+C to quit)
2021-12-22 15:21:15,700 ERROR Exception on /manager/pending/reimbursement/2 [GET]
Traceback (most recent call last):
  File "C:\Users\itsvi\Desktop\Project1\venv\lib\site-packages\flask\app.py", line 2073, in wsgi_app
    response = self.full_dispatch_request()
  File "C:\Users\itsvi\Desktop\Project1\venv\lib\site-packages\flask\app.py", line 1518, in full_dispatch_request
    rv = self.handle_user_exception(e)
  File "C:\Users\itsvi\Desktop\Project1\venv\lib\site-packages\flask\app.py", line 1516, in full_dispatch_request
    rv = self.dispatch_request()
  File "C:\Users\itsvi\Desktop\Project1\venv\lib\site-packages\flask\app.py", line 1502, in dispatch_request
    return self.ensure_sync(self.view_functions[rule.endpoint])(**req.view_args)
  File "C:\Users\itsvi\Desktop\Project1\main.py", line 143, in get_all_pending_reimbursement_by_manager_id
    reimbursement_as_reimbursement = reimbursement_service.service_get_all_pending_reimbursements_by_manager_id(
AttributeError: 'ReimbursementPostgresService' object has no attribute 'service_get_all_pending_reimbursements_by_manager_id'
2021-12-22 15:21:15,703 INFO 127.0.0.1 - - [22/Dec/2021 15:21:15] "[35m[1mGET /manager/pending/reimbursement/2 HTTP/1.1[0m" 500 -
2021-12-22 15:21:18,931 ERROR Exception on /manager/pending/reimbursement/3 [GET]
Traceback (most recent call last):
  File "C:\Users\itsvi\Desktop\Project1\venv\lib\site-packages\flask\app.py", line 2073, in wsgi_app
    response = self.full_dispatch_request()
  File "C:\Users\itsvi\Desktop\Project1\venv\lib\site-packages\flask\app.py", line 1518, in full_dispatch_request
    rv = self.handle_user_exception(e)
  File "C:\Users\itsvi\Desktop\Project1\venv\lib\site-packages\flask\app.py", line 1516, in full_dispatch_request
    rv = self.dispatch_request()
  File "C:\Users\itsvi\Desktop\Project1\venv\lib\site-packages\flask\app.py", line 1502, in dispatch_request
    return self.ensure_sync(self.view_functions[rule.endpoint])(**req.view_args)
  File "C:\Users\itsvi\Desktop\Project1\main.py", line 143, in get_all_pending_reimbursement_by_manager_id
    reimbursement_as_reimbursement = reimbursement_service.service_get_all_pending_reimbursements_by_manager_id(
AttributeError: 'ReimbursementPostgresService' object has no attribute 'service_get_all_pending_reimbursements_by_manager_id'
2021-12-22 15:21:18,932 INFO 127.0.0.1 - - [22/Dec/2021 15:21:18] "[35m[1mGET /manager/pending/reimbursement/3 HTTP/1.1[0m" 500 -
2021-12-22 15:21:27,101 ERROR Exception on /manager/pending/reimbursement/4 [GET]
Traceback (most recent call last):
  File "C:\Users\itsvi\Desktop\Project1\venv\lib\site-packages\flask\app.py", line 2073, in wsgi_app
    response = self.full_dispatch_request()
  File "C:\Users\itsvi\Desktop\Project1\venv\lib\site-packages\flask\app.py", line 1518, in full_dispatch_request
    rv = self.handle_user_exception(e)
  File "C:\Users\itsvi\Desktop\Project1\venv\lib\site-packages\flask\app.py", line 1516, in full_dispatch_request
    rv = self.dispatch_request()
  File "C:\Users\itsvi\Desktop\Project1\venv\lib\site-packages\flask\app.py", line 1502, in dispatch_request
    return self.ensure_sync(self.view_functions[rule.endpoint])(**req.view_args)
  File "C:\Users\itsvi\Desktop\Project1\main.py", line 143, in get_all_pending_reimbursement_by_manager_id
    reimbursement_as_reimbursement = reimbursement_service.service_get_all_pending_reimbursements_by_manager_id(
AttributeError: 'ReimbursementPostgresService' object has no attribute 'service_get_all_pending_reimbursements_by_manager_id'
2021-12-22 15:21:27,102 INFO 127.0.0.1 - - [22/Dec/2021 15:21:27] "[35m[1mGET /manager/pending/reimbursement/4 HTTP/1.1[0m" 500 -
2021-12-22 15:21:30,365 INFO 127.0.0.1 - - [22/Dec/2021 15:21:30] "[33mGET /manager/pending/reimbursement1 HTTP/1.1[0m" 404 -
2021-12-22 15:21:39,525 ERROR Exception on /manager/pending/reimbursement/1 [GET]
Traceback (most recent call last):
  File "C:\Users\itsvi\Desktop\Project1\venv\lib\site-packages\flask\app.py", line 2073, in wsgi_app
    response = self.full_dispatch_request()
  File "C:\Users\itsvi\Desktop\Project1\venv\lib\site-packages\flask\app.py", line 1518, in full_dispatch_request
    rv = self.handle_user_exception(e)
  File "C:\Users\itsvi\Desktop\Project1\venv\lib\site-packages\flask\app.py", line 1516, in full_dispatch_request
    rv = self.dispatch_request()
  File "C:\Users\itsvi\Desktop\Project1\venv\lib\site-packages\flask\app.py", line 1502, in dispatch_request
    return self.ensure_sync(self.view_functions[rule.endpoint])(**req.view_args)
  File "C:\Users\itsvi\Desktop\Project1\main.py", line 143, in get_all_pending_reimbursement_by_manager_id
    reimbursement_as_reimbursement = reimbursement_service.service_get_all_pending_reimbursements_by_manager_id(
AttributeError: 'ReimbursementPostgresService' object has no attribute 'service_get_all_pending_reimbursements_by_manager_id'
2021-12-22 15:21:39,526 INFO 127.0.0.1 - - [22/Dec/2021 15:21:39] "[35m[1mGET /manager/pending/reimbursement/1 HTTP/1.1[0m" 500 -
2021-12-22 15:24:54,184 INFO  * Running on http://127.0.0.1:5000/ (Press CTRL+C to quit)
2021-12-22 15:24:58,963 INFO 127.0.0.1 - - [22/Dec/2021 15:24:58] "GET /past/reimbursements/2 HTTP/1.1" 200 -
2021-12-22 15:25:19,164 ERROR Exception on /manager/pending/reimbursement/3 [GET]
Traceback (most recent call last):
  File "C:\Users\itsvi\Desktop\Project1\venv\lib\site-packages\flask\app.py", line 2073, in wsgi_app
    response = self.full_dispatch_request()
  File "C:\Users\itsvi\Desktop\Project1\venv\lib\site-packages\flask\app.py", line 1518, in full_dispatch_request
    rv = self.handle_user_exception(e)
  File "C:\Users\itsvi\Desktop\Project1\venv\lib\site-packages\flask\app.py", line 1516, in full_dispatch_request
    rv = self.dispatch_request()
  File "C:\Users\itsvi\Desktop\Project1\venv\lib\site-packages\flask\app.py", line 1502, in dispatch_request
    return self.ensure_sync(self.view_functions[rule.endpoint])(**req.view_args)
  File "C:\Users\itsvi\Desktop\Project1\main.py", line 143, in get_all_pending_reimbursement_by_manager_id
    reimbursement_as_reimbursement = reimbursement_service.service_get_all_pending_reimbursement_by_manager_id(
  File "C:\Users\itsvi\Desktop\Project1\service_layer\service_imp\reimbursement_postgres_service.py", line 91, in service_get_all_pending_reimbursement_by_manager_id
    return self.reimbursement_dao.get_all_pending_reimbursement_by_manager_id(manager_id)
  File "C:\Users\itsvi\Desktop\Project1\data_access_layer\dao_imp\reimbursement_imp_dao.py", line 23, in get_all_pending_reimbursement_by_manager_id
    cursor.execute(sql, [manager_id])
  File "C:\Users\itsvi\Desktop\Project1\venv\lib\site-packages\psycopg\cursor.py", line 561, in execute
    raise ex.with_traceback(None)
psycopg.errors.UndefinedColumn: column "approval" does not exist
LINE 1: ...ct * from reimbursement where manager_id = $1 and approval =...
                                                             ^
2021-12-22 15:25:19,205 INFO 127.0.0.1 - - [22/Dec/2021 15:25:19] "[35m[1mGET /manager/pending/reimbursement/3 HTTP/1.1[0m" 500 -
2021-12-22 15:26:26,952 ERROR Exception on /manager/pending/reimbursement/20 [GET]
Traceback (most recent call last):
  File "C:\Users\itsvi\Desktop\Project1\venv\lib\site-packages\flask\app.py", line 2073, in wsgi_app
    response = self.full_dispatch_request()
  File "C:\Users\itsvi\Desktop\Project1\venv\lib\site-packages\flask\app.py", line 1518, in full_dispatch_request
    rv = self.handle_user_exception(e)
  File "C:\Users\itsvi\Desktop\Project1\venv\lib\site-packages\flask\app.py", line 1516, in full_dispatch_request
    rv = self.dispatch_request()
  File "C:\Users\itsvi\Desktop\Project1\venv\lib\site-packages\flask\app.py", line 1502, in dispatch_request
    return self.ensure_sync(self.view_functions[rule.endpoint])(**req.view_args)
  File "C:\Users\itsvi\Desktop\Project1\main.py", line 143, in get_all_pending_reimbursement_by_manager_id
    reimbursement_as_reimbursement = reimbursement_service.service_get_all_pending_reimbursement_by_manager_id(
  File "C:\Users\itsvi\Desktop\Project1\service_layer\service_imp\reimbursement_postgres_service.py", line 87, in service_get_all_pending_reimbursement_by_manager_id
    reimbursement_list = self.reimbursement_dao.select_get_all_reimbursement_information()
  File "C:\Users\itsvi\Desktop\Project1\data_access_layer\dao_imp\reimbursement_imp_dao.py", line 56, in select_get_all_reimbursement_information
    cursor.execute(sql)
  File "C:\Users\itsvi\Desktop\Project1\venv\lib\site-packages\psycopg\cursor.py", line 561, in execute
    raise ex.with_traceback(None)
psycopg.errors.InFailedSqlTransaction: current transaction is aborted, commands ignored until end of transaction block
2021-12-22 15:26:26,953 INFO 127.0.0.1 - - [22/Dec/2021 15:26:26] "[35m[1mGET /manager/pending/reimbursement/20 HTTP/1.1[0m" 500 -
2021-12-22 15:26:30,801 ERROR Exception on /manager/pending/reimbursement/2 [GET]
Traceback (most recent call last):
  File "C:\Users\itsvi\Desktop\Project1\venv\lib\site-packages\flask\app.py", line 2073, in wsgi_app
    response = self.full_dispatch_request()
  File "C:\Users\itsvi\Desktop\Project1\venv\lib\site-packages\flask\app.py", line 1518, in full_dispatch_request
    rv = self.handle_user_exception(e)
  File "C:\Users\itsvi\Desktop\Project1\venv\lib\site-packages\flask\app.py", line 1516, in full_dispatch_request
    rv = self.dispatch_request()
  File "C:\Users\itsvi\Desktop\Project1\venv\lib\site-packages\flask\app.py", line 1502, in dispatch_request
    return self.ensure_sync(self.view_functions[rule.endpoint])(**req.view_args)
  File "C:\Users\itsvi\Desktop\Project1\main.py", line 143, in get_all_pending_reimbursement_by_manager_id
    reimbursement_as_reimbursement = reimbursement_service.service_get_all_pending_reimbursement_by_manager_id(
  File "C:\Users\itsvi\Desktop\Project1\service_layer\service_imp\reimbursement_postgres_service.py", line 87, in service_get_all_pending_reimbursement_by_manager_id
    reimbursement_list = self.reimbursement_dao.select_get_all_reimbursement_information()
  File "C:\Users\itsvi\Desktop\Project1\data_access_layer\dao_imp\reimbursement_imp_dao.py", line 56, in select_get_all_reimbursement_information
    cursor.execute(sql)
  File "C:\Users\itsvi\Desktop\Project1\venv\lib\site-packages\psycopg\cursor.py", line 561, in execute
    raise ex.with_traceback(None)
psycopg.errors.InFailedSqlTransaction: current transaction is aborted, commands ignored until end of transaction block
2021-12-22 15:26:30,802 INFO 127.0.0.1 - - [22/Dec/2021 15:26:30] "[35m[1mGET /manager/pending/reimbursement/2 HTTP/1.1[0m" 500 -
2021-12-22 15:26:33,252 ERROR Exception on /manager/pending/reimbursement/3 [GET]
Traceback (most recent call last):
  File "C:\Users\itsvi\Desktop\Project1\venv\lib\site-packages\flask\app.py", line 2073, in wsgi_app
    response = self.full_dispatch_request()
  File "C:\Users\itsvi\Desktop\Project1\venv\lib\site-packages\flask\app.py", line 1518, in full_dispatch_request
    rv = self.handle_user_exception(e)
  File "C:\Users\itsvi\Desktop\Project1\venv\lib\site-packages\flask\app.py", line 1516, in full_dispatch_request
    rv = self.dispatch_request()
  File "C:\Users\itsvi\Desktop\Project1\venv\lib\site-packages\flask\app.py", line 1502, in dispatch_request
    return self.ensure_sync(self.view_functions[rule.endpoint])(**req.view_args)
  File "C:\Users\itsvi\Desktop\Project1\main.py", line 143, in get_all_pending_reimbursement_by_manager_id
    reimbursement_as_reimbursement = reimbursement_service.service_get_all_pending_reimbursement_by_manager_id(
  File "C:\Users\itsvi\Desktop\Project1\service_layer\service_imp\reimbursement_postgres_service.py", line 87, in service_get_all_pending_reimbursement_by_manager_id
    reimbursement_list = self.reimbursement_dao.select_get_all_reimbursement_information()
  File "C:\Users\itsvi\Desktop\Project1\data_access_layer\dao_imp\reimbursement_imp_dao.py", line 56, in select_get_all_reimbursement_information
    cursor.execute(sql)
  File "C:\Users\itsvi\Desktop\Project1\venv\lib\site-packages\psycopg\cursor.py", line 561, in execute
    raise ex.with_traceback(None)
psycopg.errors.InFailedSqlTransaction: current transaction is aborted, commands ignored until end of transaction block
2021-12-22 15:26:33,254 INFO 127.0.0.1 - - [22/Dec/2021 15:26:33] "[35m[1mGET /manager/pending/reimbursement/3 HTTP/1.1[0m" 500 -
2021-12-22 15:26:35,953 ERROR Exception on /manager/pending/reimbursement/4 [GET]
Traceback (most recent call last):
  File "C:\Users\itsvi\Desktop\Project1\venv\lib\site-packages\flask\app.py", line 2073, in wsgi_app
    response = self.full_dispatch_request()
  File "C:\Users\itsvi\Desktop\Project1\venv\lib\site-packages\flask\app.py", line 1518, in full_dispatch_request
    rv = self.handle_user_exception(e)
  File "C:\Users\itsvi\Desktop\Project1\venv\lib\site-packages\flask\app.py", line 1516, in full_dispatch_request
    rv = self.dispatch_request()
  File "C:\Users\itsvi\Desktop\Project1\venv\lib\site-packages\flask\app.py", line 1502, in dispatch_request
    return self.ensure_sync(self.view_functions[rule.endpoint])(**req.view_args)
  File "C:\Users\itsvi\Desktop\Project1\main.py", line 143, in get_all_pending_reimbursement_by_manager_id
    reimbursement_as_reimbursement = reimbursement_service.service_get_all_pending_reimbursement_by_manager_id(
  File "C:\Users\itsvi\Desktop\Project1\service_layer\service_imp\reimbursement_postgres_service.py", line 87, in service_get_all_pending_reimbursement_by_manager_id
    reimbursement_list = self.reimbursement_dao.select_get_all_reimbursement_information()
  File "C:\Users\itsvi\Desktop\Project1\data_access_layer\dao_imp\reimbursement_imp_dao.py", line 56, in select_get_all_reimbursement_information
    cursor.execute(sql)
  File "C:\Users\itsvi\Desktop\Project1\venv\lib\site-packages\psycopg\cursor.py", line 561, in execute
    raise ex.with_traceback(None)
psycopg.errors.InFailedSqlTransaction: current transaction is aborted, commands ignored until end of transaction block
2021-12-22 15:26:35,955 INFO 127.0.0.1 - - [22/Dec/2021 15:26:35] "[35m[1mGET /manager/pending/reimbursement/4 HTTP/1.1[0m" 500 -
2021-12-22 15:27:51,809 ERROR Exception on /manager/pending/reimbursement/4 [GET]
Traceback (most recent call last):
  File "C:\Users\itsvi\Desktop\Project1\venv\lib\site-packages\flask\app.py", line 2073, in wsgi_app
    response = self.full_dispatch_request()
  File "C:\Users\itsvi\Desktop\Project1\venv\lib\site-packages\flask\app.py", line 1518, in full_dispatch_request
    rv = self.handle_user_exception(e)
  File "C:\Users\itsvi\Desktop\Project1\venv\lib\site-packages\flask\app.py", line 1516, in full_dispatch_request
    rv = self.dispatch_request()
  File "C:\Users\itsvi\Desktop\Project1\venv\lib\site-packages\flask\app.py", line 1502, in dispatch_request
    return self.ensure_sync(self.view_functions[rule.endpoint])(**req.view_args)
  File "C:\Users\itsvi\Desktop\Project1\main.py", line 143, in get_all_pending_reimbursement_by_manager_id
    reimbursement_as_reimbursement = reimbursement_service.service_get_all_pending_reimbursement_by_manager_id(
  File "C:\Users\itsvi\Desktop\Project1\service_layer\service_imp\reimbursement_postgres_service.py", line 87, in service_get_all_pending_reimbursement_by_manager_id
    reimbursement_list = self.reimbursement_dao.select_get_all_reimbursement_information()
  File "C:\Users\itsvi\Desktop\Project1\data_access_layer\dao_imp\reimbursement_imp_dao.py", line 56, in select_get_all_reimbursement_information
    cursor.execute(sql)
  File "C:\Users\itsvi\Desktop\Project1\venv\lib\site-packages\psycopg\cursor.py", line 561, in execute
    raise ex.with_traceback(None)
psycopg.errors.InFailedSqlTransaction: current transaction is aborted, commands ignored until end of transaction block
2021-12-22 15:27:51,812 INFO 127.0.0.1 - - [22/Dec/2021 15:27:51] "[35m[1mGET /manager/pending/reimbursement/4 HTTP/1.1[0m" 500 -
2021-12-22 15:27:59,811 ERROR Exception on /manager/pending/reimbursement/4 [GET]
Traceback (most recent call last):
  File "C:\Users\itsvi\Desktop\Project1\venv\lib\site-packages\flask\app.py", line 2073, in wsgi_app
    response = self.full_dispatch_request()
  File "C:\Users\itsvi\Desktop\Project1\venv\lib\site-packages\flask\app.py", line 1518, in full_dispatch_request
    rv = self.handle_user_exception(e)
  File "C:\Users\itsvi\Desktop\Project1\venv\lib\site-packages\flask\app.py", line 1516, in full_dispatch_request
    rv = self.dispatch_request()
  File "C:\Users\itsvi\Desktop\Project1\venv\lib\site-packages\flask\app.py", line 1502, in dispatch_request
    return self.ensure_sync(self.view_functions[rule.endpoint])(**req.view_args)
  File "C:\Users\itsvi\Desktop\Project1\main.py", line 143, in get_all_pending_reimbursement_by_manager_id
    reimbursement_as_reimbursement = reimbursement_service.service_get_all_pending_reimbursement_by_manager_id(
  File "C:\Users\itsvi\Desktop\Project1\service_layer\service_imp\reimbursement_postgres_service.py", line 87, in service_get_all_pending_reimbursement_by_manager_id
    reimbursement_list = self.reimbursement_dao.select_get_all_reimbursement_information()
  File "C:\Users\itsvi\Desktop\Project1\data_access_layer\dao_imp\reimbursement_imp_dao.py", line 56, in select_get_all_reimbursement_information
    cursor.execute(sql)
  File "C:\Users\itsvi\Desktop\Project1\venv\lib\site-packages\psycopg\cursor.py", line 561, in execute
    raise ex.with_traceback(None)
psycopg.errors.InFailedSqlTransaction: current transaction is aborted, commands ignored until end of transaction block
2021-12-22 15:27:59,812 INFO 127.0.0.1 - - [22/Dec/2021 15:27:59] "[35m[1mGET /manager/pending/reimbursement/4 HTTP/1.1[0m" 500 -
2021-12-22 15:28:03,524 ERROR Exception on /manager/pending/reimbursement/2 [GET]
Traceback (most recent call last):
  File "C:\Users\itsvi\Desktop\Project1\venv\lib\site-packages\flask\app.py", line 2073, in wsgi_app
    response = self.full_dispatch_request()
  File "C:\Users\itsvi\Desktop\Project1\venv\lib\site-packages\flask\app.py", line 1518, in full_dispatch_request
    rv = self.handle_user_exception(e)
  File "C:\Users\itsvi\Desktop\Project1\venv\lib\site-packages\flask\app.py", line 1516, in full_dispatch_request
    rv = self.dispatch_request()
  File "C:\Users\itsvi\Desktop\Project1\venv\lib\site-packages\flask\app.py", line 1502, in dispatch_request
    return self.ensure_sync(self.view_functions[rule.endpoint])(**req.view_args)
  File "C:\Users\itsvi\Desktop\Project1\main.py", line 143, in get_all_pending_reimbursement_by_manager_id
    reimbursement_as_reimbursement = reimbursement_service.service_get_all_pending_reimbursement_by_manager_id(
  File "C:\Users\itsvi\Desktop\Project1\service_layer\service_imp\reimbursement_postgres_service.py", line 87, in service_get_all_pending_reimbursement_by_manager_id
    reimbursement_list = self.reimbursement_dao.select_get_all_reimbursement_information()
  File "C:\Users\itsvi\Desktop\Project1\data_access_layer\dao_imp\reimbursement_imp_dao.py", line 56, in select_get_all_reimbursement_information
    cursor.execute(sql)
  File "C:\Users\itsvi\Desktop\Project1\venv\lib\site-packages\psycopg\cursor.py", line 561, in execute
    raise ex.with_traceback(None)
psycopg.errors.InFailedSqlTransaction: current transaction is aborted, commands ignored until end of transaction block
2021-12-22 15:28:03,526 INFO 127.0.0.1 - - [22/Dec/2021 15:28:03] "[35m[1mGET /manager/pending/reimbursement/2 HTTP/1.1[0m" 500 -
2021-12-22 15:28:04,641 ERROR Exception on /manager/pending/reimbursement/2 [GET]
Traceback (most recent call last):
  File "C:\Users\itsvi\Desktop\Project1\venv\lib\site-packages\flask\app.py", line 2073, in wsgi_app
    response = self.full_dispatch_request()
  File "C:\Users\itsvi\Desktop\Project1\venv\lib\site-packages\flask\app.py", line 1518, in full_dispatch_request
    rv = self.handle_user_exception(e)
  File "C:\Users\itsvi\Desktop\Project1\venv\lib\site-packages\flask\app.py", line 1516, in full_dispatch_request
    rv = self.dispatch_request()
  File "C:\Users\itsvi\Desktop\Project1\venv\lib\site-packages\flask\app.py", line 1502, in dispatch_request
    return self.ensure_sync(self.view_functions[rule.endpoint])(**req.view_args)
  File "C:\Users\itsvi\Desktop\Project1\main.py", line 143, in get_all_pending_reimbursement_by_manager_id
    reimbursement_as_reimbursement = reimbursement_service.service_get_all_pending_reimbursement_by_manager_id(
  File "C:\Users\itsvi\Desktop\Project1\service_layer\service_imp\reimbursement_postgres_service.py", line 87, in service_get_all_pending_reimbursement_by_manager_id
    reimbursement_list = self.reimbursement_dao.select_get_all_reimbursement_information()
  File "C:\Users\itsvi\Desktop\Project1\data_access_layer\dao_imp\reimbursement_imp_dao.py", line 56, in select_get_all_reimbursement_information
    cursor.execute(sql)
  File "C:\Users\itsvi\Desktop\Project1\venv\lib\site-packages\psycopg\cursor.py", line 561, in execute
    raise ex.with_traceback(None)
psycopg.errors.InFailedSqlTransaction: current transaction is aborted, commands ignored until end of transaction block
2021-12-22 15:28:04,643 INFO 127.0.0.1 - - [22/Dec/2021 15:28:04] "[35m[1mGET /manager/pending/reimbursement/2 HTTP/1.1[0m" 500 -
2021-12-22 15:30:51,719 INFO  * Running on http://127.0.0.1:5000/ (Press CTRL+C to quit)
2021-12-22 15:30:54,851 ERROR Exception on /manager/pending/reimbursement/3 [GET]
Traceback (most recent call last):
  File "C:\Users\itsvi\Desktop\Project1\venv\lib\site-packages\flask\app.py", line 2073, in wsgi_app
    response = self.full_dispatch_request()
  File "C:\Users\itsvi\Desktop\Project1\venv\lib\site-packages\flask\app.py", line 1518, in full_dispatch_request
    rv = self.handle_user_exception(e)
  File "C:\Users\itsvi\Desktop\Project1\venv\lib\site-packages\flask\app.py", line 1516, in full_dispatch_request
    rv = self.dispatch_request()
  File "C:\Users\itsvi\Desktop\Project1\venv\lib\site-packages\flask\app.py", line 1502, in dispatch_request
    return self.ensure_sync(self.view_functions[rule.endpoint])(**req.view_args)
  File "C:\Users\itsvi\Desktop\Project1\main.py", line 143, in get_all_pending_reimbursement_by_manager_id
    reimbursement_as_reimbursement = reimbursement_service.service_get_all_pending_reimbursement_by_manager_id(
  File "C:\Users\itsvi\Desktop\Project1\service_layer\service_imp\reimbursement_postgres_service.py", line 91, in service_get_all_pending_reimbursement_by_manager_id
    return self.reimbursement_dao.get_all_pending_reimbursement_by_manager_id(manager_id)
  File "C:\Users\itsvi\Desktop\Project1\data_access_layer\dao_imp\reimbursement_imp_dao.py", line 23, in get_all_pending_reimbursement_by_manager_id
    cursor.execute(sql, [manager_id])
  File "C:\Users\itsvi\Desktop\Project1\venv\lib\site-packages\psycopg\cursor.py", line 561, in execute
    raise ex.with_traceback(None)
psycopg.errors.UndefinedColumn: column "approval" does not exist
LINE 1: ...ct * from reimbursement where manager_id = $1 and approval =...
                                                             ^
2021-12-22 15:30:54,855 INFO 127.0.0.1 - - [22/Dec/2021 15:30:54] "[35m[1mGET /manager/pending/reimbursement/3 HTTP/1.1[0m" 500 -
2021-12-22 15:33:05,643 INFO  * Running on http://127.0.0.1:5000/ (Press CTRL+C to quit)
2021-12-22 15:33:07,528 INFO 127.0.0.1 - - [22/Dec/2021 15:33:07] "GET /manager/pending/reimbursement/3 HTTP/1.1" 200 -
2021-12-22 15:33:14,332 ERROR Exception on /manager/pending/reimbursement/4 [GET]
Traceback (most recent call last):
  File "C:\Users\itsvi\Desktop\Project1\venv\lib\site-packages\flask\app.py", line 2073, in wsgi_app
    response = self.full_dispatch_request()
  File "C:\Users\itsvi\Desktop\Project1\venv\lib\site-packages\flask\app.py", line 1518, in full_dispatch_request
    rv = self.handle_user_exception(e)
  File "C:\Users\itsvi\Desktop\Project1\venv\lib\site-packages\flask\app.py", line 1516, in full_dispatch_request
    rv = self.dispatch_request()
  File "C:\Users\itsvi\Desktop\Project1\venv\lib\site-packages\flask\app.py", line 1502, in dispatch_request
    return self.ensure_sync(self.view_functions[rule.endpoint])(**req.view_args)
  File "C:\Users\itsvi\Desktop\Project1\main.py", line 143, in get_all_pending_reimbursement_by_manager_id
    reimbursement_as_reimbursement = reimbursement_service.service_get_all_pending_reimbursement_by_manager_id(
  File "C:\Users\itsvi\Desktop\Project1\service_layer\service_imp\reimbursement_postgres_service.py", line 92, in service_get_all_pending_reimbursement_by_manager_id
    raise ManagerNonexistException("Does not exist.")
custom_exceptions.manager_nonexist_exception.ManagerNonexistException: Does not exist.
2021-12-22 15:33:14,334 INFO 127.0.0.1 - - [22/Dec/2021 15:33:14] "[35m[1mGET /manager/pending/reimbursement/4 HTTP/1.1[0m" 500 -
2021-12-22 15:33:18,257 INFO 127.0.0.1 - - [22/Dec/2021 15:33:18] "GET /manager/pending/reimbursement/10 HTTP/1.1" 200 -
2021-12-22 16:07:09,182 INFO 127.0.0.1 - - [22/Dec/2021 16:07:09] "[33mGET /manager/2 HTTP/1.1[0m" 404 -
2021-12-22 16:07:13,856 INFO  * Running on http://127.0.0.1:5000/ (Press CTRL+C to quit)
2021-12-22 16:07:34,949 INFO  * Running on http://127.0.0.1:5000/ (Press CTRL+C to quit)
2021-12-22 16:07:39,526 INFO 127.0.0.1 - - [22/Dec/2021 16:07:39] "GET /manager/2 HTTP/1.1" 200 -
2021-12-22 16:49:03,294 INFO  * Running on http://127.0.0.1:5000/ (Press CTRL+C to quit)
2021-12-22 16:49:06,568 ERROR Exception on /reimbursement/approve/1 [PATCH]
Traceback (most recent call last):
  File "C:\Users\itsvi\Desktop\Project1\venv\lib\site-packages\flask\app.py", line 2073, in wsgi_app
    response = self.full_dispatch_request()
  File "C:\Users\itsvi\Desktop\Project1\venv\lib\site-packages\flask\app.py", line 1518, in full_dispatch_request
    rv = self.handle_user_exception(e)
  File "C:\Users\itsvi\Desktop\Project1\venv\lib\site-packages\flask\app.py", line 1516, in full_dispatch_request
    rv = self.dispatch_request()
  File "C:\Users\itsvi\Desktop\Project1\venv\lib\site-packages\flask\app.py", line 1502, in dispatch_request
    return self.ensure_sync(self.view_functions[rule.endpoint])(**req.view_args)
  File "C:\Users\itsvi\Desktop\Project1\main.py", line 218, in service_approve_reimbursement
    reimbursement_to_return = reimbursement_service.service_approve_reimbursement(new_reimbursement)
  File "C:\Users\itsvi\Desktop\Project1\service_layer\service_imp\reimbursement_postgres_service.py", line 60, in service_approve_reimbursement
    raise ManagerNonexistException("Does not exist.")
custom_exceptions.manager_nonexist_exception.ManagerNonexistException: Does not exist.
2021-12-22 16:49:06,571 INFO 127.0.0.1 - - [22/Dec/2021 16:49:06] "[35m[1mPATCH /reimbursement/approve/1 HTTP/1.1[0m" 500 -
2021-12-22 16:49:45,932 ERROR Exception on /reimbursement/approve/5 [PATCH]
Traceback (most recent call last):
  File "C:\Users\itsvi\Desktop\Project1\venv\lib\site-packages\flask\app.py", line 2073, in wsgi_app
    response = self.full_dispatch_request()
  File "C:\Users\itsvi\Desktop\Project1\venv\lib\site-packages\flask\app.py", line 1518, in full_dispatch_request
    rv = self.handle_user_exception(e)
  File "C:\Users\itsvi\Desktop\Project1\venv\lib\site-packages\flask\app.py", line 1516, in full_dispatch_request
    rv = self.dispatch_request()
  File "C:\Users\itsvi\Desktop\Project1\venv\lib\site-packages\flask\app.py", line 1502, in dispatch_request
    return self.ensure_sync(self.view_functions[rule.endpoint])(**req.view_args)
  File "C:\Users\itsvi\Desktop\Project1\main.py", line 218, in service_approve_reimbursement
    reimbursement_to_return = reimbursement_service.service_approve_reimbursement(new_reimbursement)
  File "C:\Users\itsvi\Desktop\Project1\service_layer\service_imp\reimbursement_postgres_service.py", line 59, in service_approve_reimbursement
    raise EmployeeNonexistException("Does not exist.")
custom_exceptions.employee_nonexist_exception.EmployeeNonexistException: Does not exist.
2021-12-22 16:49:45,934 INFO 127.0.0.1 - - [22/Dec/2021 16:49:45] "[35m[1mPATCH /reimbursement/approve/5 HTTP/1.1[0m" 500 -
2021-12-22 16:50:06,770 INFO 127.0.0.1 - - [22/Dec/2021 16:50:06] "[33mPATCH /reimbursement/accept/5 HTTP/1.1[0m" 404 -
2021-12-22 16:50:14,810 INFO  * Running on http://127.0.0.1:5000/ (Press CTRL+C to quit)
2021-12-22 16:50:17,138 ERROR Exception on /reimbursement/accept/5 [PATCH]
Traceback (most recent call last):
  File "C:\Users\itsvi\Desktop\Project1\venv\lib\site-packages\flask\app.py", line 2073, in wsgi_app
    response = self.full_dispatch_request()
  File "C:\Users\itsvi\Desktop\Project1\venv\lib\site-packages\flask\app.py", line 1518, in full_dispatch_request
    rv = self.handle_user_exception(e)
  File "C:\Users\itsvi\Desktop\Project1\venv\lib\site-packages\flask\app.py", line 1516, in full_dispatch_request
    rv = self.dispatch_request()
  File "C:\Users\itsvi\Desktop\Project1\venv\lib\site-packages\flask\app.py", line 1502, in dispatch_request
    return self.ensure_sync(self.view_functions[rule.endpoint])(**req.view_args)
  File "C:\Users\itsvi\Desktop\Project1\main.py", line 218, in service_approve_reimbursement
    reimbursement_to_return = reimbursement_service.service_approve_reimbursement(new_reimbursement)
  File "C:\Users\itsvi\Desktop\Project1\service_layer\service_imp\reimbursement_postgres_service.py", line 59, in service_approve_reimbursement
    raise EmployeeNonexistException("Does not exist.")
custom_exceptions.employee_nonexist_exception.EmployeeNonexistException: Does not exist.
2021-12-22 16:50:17,141 INFO 127.0.0.1 - - [22/Dec/2021 16:50:17] "[35m[1mPATCH /reimbursement/accept/5 HTTP/1.1[0m" 500 -
2021-12-22 16:51:19,659 ERROR Exception on /reimbursement/accept/33 [PATCH]
Traceback (most recent call last):
  File "C:\Users\itsvi\Desktop\Project1\venv\lib\site-packages\flask\app.py", line 2073, in wsgi_app
    response = self.full_dispatch_request()
  File "C:\Users\itsvi\Desktop\Project1\venv\lib\site-packages\flask\app.py", line 1518, in full_dispatch_request
    rv = self.handle_user_exception(e)
  File "C:\Users\itsvi\Desktop\Project1\venv\lib\site-packages\flask\app.py", line 1516, in full_dispatch_request
    rv = self.dispatch_request()
  File "C:\Users\itsvi\Desktop\Project1\venv\lib\site-packages\flask\app.py", line 1502, in dispatch_request
    return self.ensure_sync(self.view_functions[rule.endpoint])(**req.view_args)
  File "C:\Users\itsvi\Desktop\Project1\main.py", line 218, in service_approve_reimbursement
    reimbursement_to_return = reimbursement_service.service_approve_reimbursement(new_reimbursement)
  File "C:\Users\itsvi\Desktop\Project1\service_layer\service_imp\reimbursement_postgres_service.py", line 60, in service_approve_reimbursement
    raise ManagerNonexistException("Does not exist.")
custom_exceptions.manager_nonexist_exception.ManagerNonexistException: Does not exist.
2021-12-22 16:51:19,660 INFO 127.0.0.1 - - [22/Dec/2021 16:51:19] "[35m[1mPATCH /reimbursement/accept/33 HTTP/1.1[0m" 500 -
2021-12-22 16:51:23,729 INFO  * Running on http://127.0.0.1:5000/ (Press CTRL+C to quit)
2021-12-22 16:51:26,974 ERROR Exception on /reimbursement/accept/33 [PATCH]
Traceback (most recent call last):
  File "C:\Users\itsvi\Desktop\Project1\venv\lib\site-packages\flask\app.py", line 2073, in wsgi_app
    response = self.full_dispatch_request()
  File "C:\Users\itsvi\Desktop\Project1\venv\lib\site-packages\flask\app.py", line 1518, in full_dispatch_request
    rv = self.handle_user_exception(e)
  File "C:\Users\itsvi\Desktop\Project1\venv\lib\site-packages\flask\app.py", line 1516, in full_dispatch_request
    rv = self.dispatch_request()
  File "C:\Users\itsvi\Desktop\Project1\venv\lib\site-packages\flask\app.py", line 1502, in dispatch_request
    return self.ensure_sync(self.view_functions[rule.endpoint])(**req.view_args)
  File "C:\Users\itsvi\Desktop\Project1\main.py", line 218, in service_approve_reimbursement
    reimbursement_to_return = reimbursement_service.service_approve_reimbursement(new_reimbursement)
  File "C:\Users\itsvi\Desktop\Project1\service_layer\service_imp\reimbursement_postgres_service.py", line 60, in service_approve_reimbursement
    raise ManagerNonexistException("Does not exist.")
custom_exceptions.manager_nonexist_exception.ManagerNonexistException: Does not exist.
2021-12-22 16:51:26,976 INFO 127.0.0.1 - - [22/Dec/2021 16:51:26] "[35m[1mPATCH /reimbursement/accept/33 HTTP/1.1[0m" 500 -
2021-12-22 16:51:58,563 ERROR Exception on /reimbursement/accept/33 [PATCH]
Traceback (most recent call last):
  File "C:\Users\itsvi\Desktop\Project1\venv\lib\site-packages\flask\app.py", line 2073, in wsgi_app
    response = self.full_dispatch_request()
  File "C:\Users\itsvi\Desktop\Project1\venv\lib\site-packages\flask\app.py", line 1518, in full_dispatch_request
    rv = self.handle_user_exception(e)
  File "C:\Users\itsvi\Desktop\Project1\venv\lib\site-packages\flask\app.py", line 1516, in full_dispatch_request
    rv = self.dispatch_request()
  File "C:\Users\itsvi\Desktop\Project1\venv\lib\site-packages\flask\app.py", line 1502, in dispatch_request
    return self.ensure_sync(self.view_functions[rule.endpoint])(**req.view_args)
  File "C:\Users\itsvi\Desktop\Project1\main.py", line 218, in service_approve_reimbursement
    reimbursement_to_return = reimbursement_service.service_approve_reimbursement(new_reimbursement)
  File "C:\Users\itsvi\Desktop\Project1\service_layer\service_imp\reimbursement_postgres_service.py", line 60, in service_approve_reimbursement
    raise ManagerNonexistException("Does not exist.")
custom_exceptions.manager_nonexist_exception.ManagerNonexistException: Does not exist.
2021-12-22 16:51:58,565 INFO 127.0.0.1 - - [22/Dec/2021 16:51:58] "[35m[1mPATCH /reimbursement/accept/33 HTTP/1.1[0m" 500 -
2021-12-22 16:52:02,155 INFO  * Running on http://127.0.0.1:5000/ (Press CTRL+C to quit)
2021-12-22 16:52:05,644 ERROR Exception on /reimbursement/accept/33 [PATCH]
Traceback (most recent call last):
  File "C:\Users\itsvi\Desktop\Project1\venv\lib\site-packages\flask\app.py", line 2073, in wsgi_app
    response = self.full_dispatch_request()
  File "C:\Users\itsvi\Desktop\Project1\venv\lib\site-packages\flask\app.py", line 1518, in full_dispatch_request
    rv = self.handle_user_exception(e)
  File "C:\Users\itsvi\Desktop\Project1\venv\lib\site-packages\flask\app.py", line 1516, in full_dispatch_request
    rv = self.dispatch_request()
  File "C:\Users\itsvi\Desktop\Project1\venv\lib\site-packages\flask\app.py", line 1502, in dispatch_request
    return self.ensure_sync(self.view_functions[rule.endpoint])(**req.view_args)
  File "C:\Users\itsvi\Desktop\Project1\main.py", line 218, in service_approve_reimbursement
    reimbursement_to_return = reimbursement_service.service_approve_reimbursement(new_reimbursement)
  File "C:\Users\itsvi\Desktop\Project1\service_layer\service_imp\reimbursement_postgres_service.py", line 60, in service_approve_reimbursement
    raise ManagerNonexistException("Does not exist.")
custom_exceptions.manager_nonexist_exception.ManagerNonexistException: Does not exist.
2021-12-22 16:52:05,648 INFO 127.0.0.1 - - [22/Dec/2021 16:52:05] "[35m[1mPATCH /reimbursement/accept/33 HTTP/1.1[0m" 500 -
2021-12-22 17:01:33,510 INFO  * Running on http://127.0.0.1:5000/ (Press CTRL+C to quit)
2021-12-22 17:01:44,905 INFO 127.0.0.1 - - [22/Dec/2021 17:01:44] "PATCH /reimbursement/accept/44 HTTP/1.1" 200 -
2021-12-22 17:04:05,698 INFO  * Running on http://127.0.0.1:5000/ (Press CTRL+C to quit)
2021-12-22 17:04:08,827 INFO 127.0.0.1 - - [22/Dec/2021 17:04:08] "PATCH /reimbursement/accept/44 HTTP/1.1" 200 -
2021-12-22 17:06:37,710 ERROR Exception on /reimbursement/accept/49 [PATCH]
Traceback (most recent call last):
  File "C:\Users\itsvi\Desktop\Project1\venv\lib\site-packages\flask\app.py", line 2073, in wsgi_app
    response = self.full_dispatch_request()
  File "C:\Users\itsvi\Desktop\Project1\venv\lib\site-packages\flask\app.py", line 1518, in full_dispatch_request
    rv = self.handle_user_exception(e)
  File "C:\Users\itsvi\Desktop\Project1\venv\lib\site-packages\flask\app.py", line 1516, in full_dispatch_request
    rv = self.dispatch_request()
  File "C:\Users\itsvi\Desktop\Project1\venv\lib\site-packages\flask\app.py", line 1502, in dispatch_request
    return self.ensure_sync(self.view_functions[rule.endpoint])(**req.view_args)
  File "C:\Users\itsvi\Desktop\Project1\main.py", line 218, in service_approve_reimbursement
    reimbursement_to_return = reimbursement_service.service_approve_reimbursement(new_reimbursement)
  File "C:\Users\itsvi\Desktop\Project1\service_layer\service_imp\reimbursement_postgres_service.py", line 60, in service_approve_reimbursement
    raise ManagerNonexistException("Does not exist.")
custom_exceptions.manager_nonexist_exception.ManagerNonexistException: Does not exist.
2021-12-22 17:06:37,713 INFO 127.0.0.1 - - [22/Dec/2021 17:06:37] "[35m[1mPATCH /reimbursement/accept/49 HTTP/1.1[0m" 500 -
2021-12-22 17:06:48,355 INFO  * Running on http://127.0.0.1:5000/ (Press CTRL+C to quit)
2021-12-22 17:07:28,698 INFO 127.0.0.1 - - [22/Dec/2021 17:07:28] "PATCH /reimbursement/accept/49 HTTP/1.1" 200 -
2021-12-22 17:08:21,365 INFO 127.0.0.1 - - [22/Dec/2021 17:08:21] "PATCH /reimbursement/accept/46 HTTP/1.1" 200 -
2021-12-22 17:09:00,695 INFO 127.0.0.1 - - [22/Dec/2021 17:09:00] "PATCH /reimbursement/accept/46 HTTP/1.1" 200 -
2021-12-22 17:19:34,572 INFO  * Running on http://127.0.0.1:5000/ (Press CTRL+C to quit)
2021-12-22 17:20:14,341 INFO 127.0.0.1 - - [22/Dec/2021 17:20:14] "PATCH /reimbursement/accept/33 HTTP/1.1" 200 -
2021-12-22 17:20:29,439 INFO 127.0.0.1 - - [22/Dec/2021 17:20:29] "PATCH /reimbursement/accept/33 HTTP/1.1" 200 -
2021-12-22 17:29:07,234 INFO  * Running on http://127.0.0.1:5000/ (Press CTRL+C to quit)
2021-12-22 17:29:07,750 ERROR Exception on /reimbursement/deny/33 [PATCH]
Traceback (most recent call last):
  File "C:\Users\itsvi\Desktop\Project1\venv\lib\site-packages\flask\app.py", line 2073, in wsgi_app
    response = self.full_dispatch_request()
  File "C:\Users\itsvi\Desktop\Project1\venv\lib\site-packages\flask\app.py", line 1518, in full_dispatch_request
    rv = self.handle_user_exception(e)
  File "C:\Users\itsvi\Desktop\Project1\venv\lib\site-packages\flask\app.py", line 1516, in full_dispatch_request
    rv = self.dispatch_request()
  File "C:\Users\itsvi\Desktop\Project1\venv\lib\site-packages\flask\app.py", line 1502, in dispatch_request
    return self.ensure_sync(self.view_functions[rule.endpoint])(**req.view_args)
  File "C:\Users\itsvi\Desktop\Project1\main.py", line 233, in service_deny_reimbursement
    result["reason"],
KeyError: 'reason'
2021-12-22 17:29:07,753 INFO 127.0.0.1 - - [22/Dec/2021 17:29:07] "[35m[1mPATCH /reimbursement/deny/33 HTTP/1.1[0m" 500 -
2021-12-22 17:29:43,062 ERROR Exception on /reimbursement/deny/48 [PATCH]
Traceback (most recent call last):
  File "C:\Users\itsvi\Desktop\Project1\venv\lib\site-packages\flask\app.py", line 2073, in wsgi_app
    response = self.full_dispatch_request()
  File "C:\Users\itsvi\Desktop\Project1\venv\lib\site-packages\flask\app.py", line 1518, in full_dispatch_request
    rv = self.handle_user_exception(e)
  File "C:\Users\itsvi\Desktop\Project1\venv\lib\site-packages\flask\app.py", line 1516, in full_dispatch_request
    rv = self.dispatch_request()
  File "C:\Users\itsvi\Desktop\Project1\venv\lib\site-packages\flask\app.py", line 1502, in dispatch_request
    return self.ensure_sync(self.view_functions[rule.endpoint])(**req.view_args)
  File "C:\Users\itsvi\Desktop\Project1\main.py", line 233, in service_deny_reimbursement
    result["reason"],
KeyError: 'reason'
2021-12-22 17:29:43,063 INFO 127.0.0.1 - - [22/Dec/2021 17:29:43] "[35m[1mPATCH /reimbursement/deny/48 HTTP/1.1[0m" 500 -
2021-12-22 17:30:05,553 INFO  * Running on http://127.0.0.1:5000/ (Press CTRL+C to quit)
2021-12-22 17:30:07,804 INFO 127.0.0.1 - - [22/Dec/2021 17:30:07] "PATCH /reimbursement/deny/48 HTTP/1.1" 200 -
2021-12-22 17:30:27,970 INFO  * Running on http://127.0.0.1:5000/ (Press CTRL+C to quit)
2021-12-22 17:30:42,514 INFO 127.0.0.1 - - [22/Dec/2021 17:30:42] "PATCH /reimbursement/deny/48 HTTP/1.1" 200 -
2021-12-22 17:31:09,499 INFO 127.0.0.1 - - [22/Dec/2021 17:31:09] "PATCH /reimbursement/deny/51 HTTP/1.1" 200 -
2021-12-22 17:31:10,828 INFO 127.0.0.1 - - [22/Dec/2021 17:31:10] "PATCH /reimbursement/deny/51 HTTP/1.1" 200 -
2021-12-22 17:31:15,954 INFO  * Running on http://127.0.0.1:5000/ (Press CTRL+C to quit)
2021-12-22 17:31:16,812 INFO 127.0.0.1 - - [22/Dec/2021 17:31:16] "PATCH /reimbursement/deny/51 HTTP/1.1" 200 -
2021-12-22 17:32:34,021 INFO  * Running on http://127.0.0.1:5000/ (Press CTRL+C to quit)
2021-12-22 17:32:36,314 INFO 127.0.0.1 - - [22/Dec/2021 17:32:36] "PATCH /reimbursement/deny/51 HTTP/1.1" 200 -
2021-12-22 17:34:57,878 INFO  * Running on http://127.0.0.1:5000/ (Press CTRL+C to quit)
2021-12-22 17:35:04,332 INFO 127.0.0.1 - - [22/Dec/2021 17:35:04] "PATCH /reimbursement/deny/50 HTTP/1.1" 200 -
2021-12-22 22:34:40,713 INFO  * Running on http://127.0.0.1:5000/ (Press CTRL+C to quit)
2021-12-22 22:37:24,164 INFO  * Running on http://127.0.0.1:5000/ (Press CTRL+C to quit)
2021-12-22 23:26:32,433 INFO  * Running on http://127.0.0.1:5000/ (Press CTRL+C to quit)
2021-12-23 02:29:57,349 INFO  * Running on http://127.0.0.1:5000/ (Press CTRL+C to quit)
2021-12-23 03:00:03,497 INFO  * Running on http://127.0.0.1:5000/ (Press CTRL+C to quit)
2021-12-23 05:12:23,361 INFO 127.0.0.1 - - [23/Dec/2021 05:12:23] "OPTIONS /employee/login HTTP/1.1" 200 -
2021-12-23 05:12:23,840 INFO 127.0.0.1 - - [23/Dec/2021 05:12:23] "OPTIONS /employee/login HTTP/1.1" 200 -
2021-12-23 05:12:23,991 INFO 127.0.0.1 - - [23/Dec/2021 05:12:23] "OPTIONS /employee/login HTTP/1.1" 200 -
2021-12-23 05:12:24,153 INFO 127.0.0.1 - - [23/Dec/2021 05:12:24] "OPTIONS /employee/login HTTP/1.1" 200 -
2021-12-23 05:12:24,305 INFO 127.0.0.1 - - [23/Dec/2021 05:12:24] "OPTIONS /employee/login HTTP/1.1" 200 -
2021-12-23 05:12:24,425 INFO 127.0.0.1 - - [23/Dec/2021 05:12:24] "OPTIONS /employee/login HTTP/1.1" 200 -
2021-12-23 05:12:24,570 INFO 127.0.0.1 - - [23/Dec/2021 05:12:24] "OPTIONS /employee/login HTTP/1.1" 200 -
2021-12-23 05:12:24,710 INFO 127.0.0.1 - - [23/Dec/2021 05:12:24] "OPTIONS /employee/login HTTP/1.1" 200 -
2021-12-23 05:12:24,841 INFO 127.0.0.1 - - [23/Dec/2021 05:12:24] "OPTIONS /employee/login HTTP/1.1" 200 -
2021-12-23 05:12:24,999 INFO 127.0.0.1 - - [23/Dec/2021 05:12:24] "OPTIONS /employee/login HTTP/1.1" 200 -
2021-12-23 05:12:25,162 INFO 127.0.0.1 - - [23/Dec/2021 05:12:25] "OPTIONS /employee/login HTTP/1.1" 200 -
2021-12-23 05:12:25,325 INFO 127.0.0.1 - - [23/Dec/2021 05:12:25] "OPTIONS /employee/login HTTP/1.1" 200 -
2021-12-23 05:12:27,134 INFO 127.0.0.1 - - [23/Dec/2021 05:12:27] "OPTIONS /employee/login HTTP/1.1" 200 -
2021-12-23 05:12:27,391 INFO 127.0.0.1 - - [23/Dec/2021 05:12:27] "OPTIONS /employee/login HTTP/1.1" 200 -
2021-12-23 05:12:54,137 INFO 127.0.0.1 - - [23/Dec/2021 05:12:54] "OPTIONS /employee/login HTTP/1.1" 200 -
2021-12-23 05:12:54,288 INFO 127.0.0.1 - - [23/Dec/2021 05:12:54] "OPTIONS /employee/login HTTP/1.1" 200 -
2021-12-23 05:12:54,441 INFO 127.0.0.1 - - [23/Dec/2021 05:12:54] "OPTIONS /employee/login HTTP/1.1" 200 -
2021-12-23 05:12:54,596 INFO 127.0.0.1 - - [23/Dec/2021 05:12:54] "OPTIONS /employee/login HTTP/1.1" 200 -
2021-12-23 05:13:03,161 INFO 127.0.0.1 - - [23/Dec/2021 05:13:03] "OPTIONS /employee/login HTTP/1.1" 200 -
2021-12-23 05:13:03,427 INFO 127.0.0.1 - - [23/Dec/2021 05:13:03] "OPTIONS /employee/login HTTP/1.1" 200 -
2021-12-23 05:13:11,459 INFO  * Running on http://127.0.0.1:5000/ (Press CTRL+C to quit)
2021-12-23 05:13:13,632 INFO 127.0.0.1 - - [23/Dec/2021 05:13:13] "OPTIONS /employee/login HTTP/1.1" 200 -
2021-12-23 05:13:13,855 INFO 127.0.0.1 - - [23/Dec/2021 05:13:13] "OPTIONS /employee/login HTTP/1.1" 200 -
2021-12-23 05:13:14,106 INFO 127.0.0.1 - - [23/Dec/2021 05:13:14] "OPTIONS /employee/login HTTP/1.1" 200 -
2021-12-23 05:13:14,306 INFO 127.0.0.1 - - [23/Dec/2021 05:13:14] "OPTIONS /employee/login HTTP/1.1" 200 -
2021-12-23 05:13:14,491 INFO 127.0.0.1 - - [23/Dec/2021 05:13:14] "OPTIONS /employee/login HTTP/1.1" 200 -
2021-12-23 05:13:14,691 INFO 127.0.0.1 - - [23/Dec/2021 05:13:14] "OPTIONS /employee/login HTTP/1.1" 200 -
2021-12-23 05:14:01,608 ERROR Exception on /manager/denied [GET]
Traceback (most recent call last):
  File "C:\Users\itsvi\Desktop\Project1\venv\lib\site-packages\flask\app.py", line 2073, in wsgi_app
    response = self.full_dispatch_request()
  File "C:\Users\itsvi\Desktop\Project1\venv\lib\site-packages\flask\app.py", line 1518, in full_dispatch_request
    rv = self.handle_user_exception(e)
  File "C:\Users\itsvi\Desktop\Project1\venv\lib\site-packages\flask\app.py", line 1516, in full_dispatch_request
    rv = self.dispatch_request()
  File "C:\Users\itsvi\Desktop\Project1\venv\lib\site-packages\flask\app.py", line 1502, in dispatch_request
    return self.ensure_sync(self.view_functions[rule.endpoint])(**req.view_args)
  File "C:\Users\itsvi\Desktop\Project1\main.py", line 159, in get_manager_by_id
    result = manager_service.service_get_manager_info(manager_id)
  File "C:\Users\itsvi\Desktop\Project1\service_layer\service_imp\manager_postgres_service.py", line 19, in service_get_manager_info
    raise ManagerUserNotFoundException("Manager username was not found")
custom_exceptions.manager_user_not_found_exception.ManagerUserNotFoundException: Manager username was not found
2021-12-23 05:14:01,637 INFO 127.0.0.1 - - [23/Dec/2021 05:14:01] "[35m[1mGET /manager/denied HTTP/1.1[0m" 500 -
2021-12-23 05:14:01,648 ERROR Exception on /manager/approved [GET]
Traceback (most recent call last):
  File "C:\Users\itsvi\Desktop\Project1\venv\lib\site-packages\flask\app.py", line 2073, in wsgi_app
    response = self.full_dispatch_request()
  File "C:\Users\itsvi\Desktop\Project1\venv\lib\site-packages\flask\app.py", line 1518, in full_dispatch_request
    rv = self.handle_user_exception(e)
  File "C:\Users\itsvi\Desktop\Project1\venv\lib\site-packages\flask\app.py", line 1516, in full_dispatch_request
    rv = self.dispatch_request()
  File "C:\Users\itsvi\Desktop\Project1\venv\lib\site-packages\flask\app.py", line 1502, in dispatch_request
    return self.ensure_sync(self.view_functions[rule.endpoint])(**req.view_args)
  File "C:\Users\itsvi\Desktop\Project1\main.py", line 159, in get_manager_by_id
    result = manager_service.service_get_manager_info(manager_id)
  File "C:\Users\itsvi\Desktop\Project1\service_layer\service_imp\manager_postgres_service.py", line 19, in service_get_manager_info
    raise ManagerUserNotFoundException("Manager username was not found")
custom_exceptions.manager_user_not_found_exception.ManagerUserNotFoundException: Manager username was not found
2021-12-23 05:14:01,648 INFO 127.0.0.1 - - [23/Dec/2021 05:14:01] "[35m[1mGET /manager/approved HTTP/1.1[0m" 500 -
2021-12-23 05:14:01,691 ERROR Exception on /manager/pending [GET]
Traceback (most recent call last):
  File "C:\Users\itsvi\Desktop\Project1\venv\lib\site-packages\flask\app.py", line 2073, in wsgi_app
    response = self.full_dispatch_request()
  File "C:\Users\itsvi\Desktop\Project1\venv\lib\site-packages\flask\app.py", line 1518, in full_dispatch_request
    rv = self.handle_user_exception(e)
  File "C:\Users\itsvi\Desktop\Project1\venv\lib\site-packages\flask\app.py", line 1516, in full_dispatch_request
    rv = self.dispatch_request()
  File "C:\Users\itsvi\Desktop\Project1\venv\lib\site-packages\flask\app.py", line 1502, in dispatch_request
    return self.ensure_sync(self.view_functions[rule.endpoint])(**req.view_args)
  File "C:\Users\itsvi\Desktop\Project1\main.py", line 159, in get_manager_by_id
    result = manager_service.service_get_manager_info(manager_id)
  File "C:\Users\itsvi\Desktop\Project1\service_layer\service_imp\manager_postgres_service.py", line 19, in service_get_manager_info
    raise ManagerUserNotFoundException("Manager username was not found")
custom_exceptions.manager_user_not_found_exception.ManagerUserNotFoundException: Manager username was not found
2021-12-23 05:14:01,691 INFO 127.0.0.1 - - [23/Dec/2021 05:14:01] "[35m[1mGET /manager/pending HTTP/1.1[0m" 500 -
2021-12-23 05:14:01,740 ERROR Exception on /manager/total [GET]
Traceback (most recent call last):
  File "C:\Users\itsvi\Desktop\Project1\venv\lib\site-packages\flask\app.py", line 2073, in wsgi_app
    response = self.full_dispatch_request()
  File "C:\Users\itsvi\Desktop\Project1\venv\lib\site-packages\flask\app.py", line 1518, in full_dispatch_request
    rv = self.handle_user_exception(e)
  File "C:\Users\itsvi\Desktop\Project1\venv\lib\site-packages\flask\app.py", line 1516, in full_dispatch_request
    rv = self.dispatch_request()
  File "C:\Users\itsvi\Desktop\Project1\venv\lib\site-packages\flask\app.py", line 1502, in dispatch_request
    return self.ensure_sync(self.view_functions[rule.endpoint])(**req.view_args)
  File "C:\Users\itsvi\Desktop\Project1\main.py", line 159, in get_manager_by_id
    result = manager_service.service_get_manager_info(manager_id)
  File "C:\Users\itsvi\Desktop\Project1\service_layer\service_imp\manager_postgres_service.py", line 19, in service_get_manager_info
    raise ManagerUserNotFoundException("Manager username was not found")
custom_exceptions.manager_user_not_found_exception.ManagerUserNotFoundException: Manager username was not found
2021-12-23 05:14:01,740 INFO 127.0.0.1 - - [23/Dec/2021 05:14:01] "[35m[1mGET /manager/total HTTP/1.1[0m" 500 -
2021-12-23 05:18:34,534 INFO  * Running on http://127.0.0.1:5000/ (Press CTRL+C to quit)
2021-12-23 06:23:51,000 INFO  * Running on http://127.0.0.1:5000/ (Press CTRL+C to quit)
2021-12-23 06:24:32,835 ERROR Exception on /employee/2 [GET]
Traceback (most recent call last):
  File "C:\Users\itsvi\Desktop\Project1\venv\lib\site-packages\flask\app.py", line 2073, in wsgi_app
    response = self.full_dispatch_request()
  File "C:\Users\itsvi\Desktop\Project1\venv\lib\site-packages\flask\app.py", line 1518, in full_dispatch_request
    rv = self.handle_user_exception(e)
  File "C:\Users\itsvi\Desktop\Project1\venv\lib\site-packages\flask\app.py", line 1516, in full_dispatch_request
    rv = self.dispatch_request()
  File "C:\Users\itsvi\Desktop\Project1\venv\lib\site-packages\flask\app.py", line 1502, in dispatch_request
    return self.ensure_sync(self.view_functions[rule.endpoint])(**req.view_args)
  File "C:\Users\itsvi\Desktop\Project1\main.py", line 40, in get_employee_by_id
    result = employee_service.service_get_employee_info(employee_id)
  File "C:\Users\itsvi\Desktop\Project1\service_layer\service_imp\employee_postgres_service.py", line 19, in service_get_employee_info
    raise EmployeeUserNotFound("Employee username was not found")
custom_exceptions.employee_user_not_found_exception.EmployeeUserNotFound: Employee username was not found
2021-12-23 06:24:32,839 INFO 127.0.0.1 - - [23/Dec/2021 06:24:32] "[35m[1mGET /employee/2 HTTP/1.1[0m" 500 -
2021-12-23 06:35:03,740 INFO  * Running on http://127.0.0.1:5000/ (Press CTRL+C to quit)
2021-12-23 06:35:07,239 ERROR Exception on /employee/e2 [GET]
Traceback (most recent call last):
  File "C:\Users\itsvi\Desktop\Project1\venv\lib\site-packages\flask\app.py", line 2073, in wsgi_app
    response = self.full_dispatch_request()
  File "C:\Users\itsvi\Desktop\Project1\venv\lib\site-packages\flask\app.py", line 1518, in full_dispatch_request
    rv = self.handle_user_exception(e)
  File "C:\Users\itsvi\Desktop\Project1\venv\lib\site-packages\flask\app.py", line 1516, in full_dispatch_request
    rv = self.dispatch_request()
  File "C:\Users\itsvi\Desktop\Project1\venv\lib\site-packages\flask\app.py", line 1502, in dispatch_request
    return self.ensure_sync(self.view_functions[rule.endpoint])(**req.view_args)
  File "C:\Users\itsvi\Desktop\Project1\main.py", line 40, in get_employee_by_id
    result = employee_service.service_get_employee_info(user)
  File "C:\Users\itsvi\Desktop\Project1\service_layer\service_imp\employee_postgres_service.py", line 18, in service_get_employee_info
    return self.employee_dao.get_employee_info(user)
  File "C:\Users\itsvi\Desktop\Project1\data_access_layer\dao_imp\employee_imp_dao.py", line 16, in get_employee_info
    cursor.execute(sql, [employee_id])
  File "C:\Users\itsvi\Desktop\Project1\venv\lib\site-packages\psycopg\cursor.py", line 561, in execute
    raise ex.with_traceback(None)
psycopg.errors.InvalidTextRepresentation: invalid input syntax for integer: "e2"
2021-12-23 06:35:07,243 INFO 127.0.0.1 - - [23/Dec/2021 06:35:07] "[35m[1mGET /employee/e2 HTTP/1.1[0m" 500 -
2021-12-23 06:35:08,412 ERROR Exception on /employee/e2 [GET]
Traceback (most recent call last):
  File "C:\Users\itsvi\Desktop\Project1\venv\lib\site-packages\flask\app.py", line 2073, in wsgi_app
    response = self.full_dispatch_request()
  File "C:\Users\itsvi\Desktop\Project1\venv\lib\site-packages\flask\app.py", line 1518, in full_dispatch_request
    rv = self.handle_user_exception(e)
  File "C:\Users\itsvi\Desktop\Project1\venv\lib\site-packages\flask\app.py", line 1516, in full_dispatch_request
    rv = self.dispatch_request()
  File "C:\Users\itsvi\Desktop\Project1\venv\lib\site-packages\flask\app.py", line 1502, in dispatch_request
    return self.ensure_sync(self.view_functions[rule.endpoint])(**req.view_args)
  File "C:\Users\itsvi\Desktop\Project1\main.py", line 40, in get_employee_by_id
    result = employee_service.service_get_employee_info(user)
  File "C:\Users\itsvi\Desktop\Project1\service_layer\service_imp\employee_postgres_service.py", line 15, in service_get_employee_info
    employee_list = self.employee_dao.get_all_employees()
  File "C:\Users\itsvi\Desktop\Project1\data_access_layer\dao_imp\employee_imp_dao.py", line 24, in get_all_employees
    cursor.execute(sql)
  File "C:\Users\itsvi\Desktop\Project1\venv\lib\site-packages\psycopg\cursor.py", line 561, in execute
    raise ex.with_traceback(None)
psycopg.errors.InFailedSqlTransaction: current transaction is aborted, commands ignored until end of transaction block
2021-12-23 06:35:08,414 INFO 127.0.0.1 - - [23/Dec/2021 06:35:08] "[35m[1mGET /employee/e2 HTTP/1.1[0m" 500 -
2021-12-23 06:35:09,500 ERROR Exception on /employee/e2 [GET]
Traceback (most recent call last):
  File "C:\Users\itsvi\Desktop\Project1\venv\lib\site-packages\flask\app.py", line 2073, in wsgi_app
    response = self.full_dispatch_request()
  File "C:\Users\itsvi\Desktop\Project1\venv\lib\site-packages\flask\app.py", line 1518, in full_dispatch_request
    rv = self.handle_user_exception(e)
  File "C:\Users\itsvi\Desktop\Project1\venv\lib\site-packages\flask\app.py", line 1516, in full_dispatch_request
    rv = self.dispatch_request()
  File "C:\Users\itsvi\Desktop\Project1\venv\lib\site-packages\flask\app.py", line 1502, in dispatch_request
    return self.ensure_sync(self.view_functions[rule.endpoint])(**req.view_args)
  File "C:\Users\itsvi\Desktop\Project1\main.py", line 40, in get_employee_by_id
    result = employee_service.service_get_employee_info(user)
  File "C:\Users\itsvi\Desktop\Project1\service_layer\service_imp\employee_postgres_service.py", line 15, in service_get_employee_info
    employee_list = self.employee_dao.get_all_employees()
  File "C:\Users\itsvi\Desktop\Project1\data_access_layer\dao_imp\employee_imp_dao.py", line 24, in get_all_employees
    cursor.execute(sql)
  File "C:\Users\itsvi\Desktop\Project1\venv\lib\site-packages\psycopg\cursor.py", line 561, in execute
    raise ex.with_traceback(None)
psycopg.errors.InFailedSqlTransaction: current transaction is aborted, commands ignored until end of transaction block
2021-12-23 06:35:09,502 INFO 127.0.0.1 - - [23/Dec/2021 06:35:09] "[35m[1mGET /employee/e2 HTTP/1.1[0m" 500 -
2021-12-23 06:35:32,726 ERROR Exception on /employee/e2 [GET]
Traceback (most recent call last):
  File "C:\Users\itsvi\Desktop\Project1\venv\lib\site-packages\flask\app.py", line 2073, in wsgi_app
    response = self.full_dispatch_request()
  File "C:\Users\itsvi\Desktop\Project1\venv\lib\site-packages\flask\app.py", line 1518, in full_dispatch_request
    rv = self.handle_user_exception(e)
  File "C:\Users\itsvi\Desktop\Project1\venv\lib\site-packages\flask\app.py", line 1516, in full_dispatch_request
    rv = self.dispatch_request()
  File "C:\Users\itsvi\Desktop\Project1\venv\lib\site-packages\flask\app.py", line 1502, in dispatch_request
    return self.ensure_sync(self.view_functions[rule.endpoint])(**req.view_args)
  File "C:\Users\itsvi\Desktop\Project1\main.py", line 40, in get_employee_by_id
    result = employee_service.service_get_employee_info(user)
  File "C:\Users\itsvi\Desktop\Project1\service_layer\service_imp\employee_postgres_service.py", line 15, in service_get_employee_info
    employee_list = self.employee_dao.get_all_employees()
  File "C:\Users\itsvi\Desktop\Project1\data_access_layer\dao_imp\employee_imp_dao.py", line 24, in get_all_employees
    cursor.execute(sql)
  File "C:\Users\itsvi\Desktop\Project1\venv\lib\site-packages\psycopg\cursor.py", line 561, in execute
    raise ex.with_traceback(None)
psycopg.errors.InFailedSqlTransaction: current transaction is aborted, commands ignored until end of transaction block
2021-12-23 06:35:32,728 INFO 127.0.0.1 - - [23/Dec/2021 06:35:32] "[35m[1mGET /employee/e2 HTTP/1.1[0m" 500 -
2021-12-23 06:35:33,587 ERROR Exception on /employee/e2 [GET]
Traceback (most recent call last):
  File "C:\Users\itsvi\Desktop\Project1\venv\lib\site-packages\flask\app.py", line 2073, in wsgi_app
    response = self.full_dispatch_request()
  File "C:\Users\itsvi\Desktop\Project1\venv\lib\site-packages\flask\app.py", line 1518, in full_dispatch_request
    rv = self.handle_user_exception(e)
  File "C:\Users\itsvi\Desktop\Project1\venv\lib\site-packages\flask\app.py", line 1516, in full_dispatch_request
    rv = self.dispatch_request()
  File "C:\Users\itsvi\Desktop\Project1\venv\lib\site-packages\flask\app.py", line 1502, in dispatch_request
    return self.ensure_sync(self.view_functions[rule.endpoint])(**req.view_args)
  File "C:\Users\itsvi\Desktop\Project1\main.py", line 40, in get_employee_by_id
    result = employee_service.service_get_employee_info(user)
  File "C:\Users\itsvi\Desktop\Project1\service_layer\service_imp\employee_postgres_service.py", line 15, in service_get_employee_info
    employee_list = self.employee_dao.get_all_employees()
  File "C:\Users\itsvi\Desktop\Project1\data_access_layer\dao_imp\employee_imp_dao.py", line 24, in get_all_employees
    cursor.execute(sql)
  File "C:\Users\itsvi\Desktop\Project1\venv\lib\site-packages\psycopg\cursor.py", line 561, in execute
    raise ex.with_traceback(None)
psycopg.errors.InFailedSqlTransaction: current transaction is aborted, commands ignored until end of transaction block
2021-12-23 06:35:33,588 INFO 127.0.0.1 - - [23/Dec/2021 06:35:33] "[35m[1mGET /employee/e2 HTTP/1.1[0m" 500 -
2021-12-23 06:35:36,785 ERROR Exception on /employee/e1 [GET]
Traceback (most recent call last):
  File "C:\Users\itsvi\Desktop\Project1\venv\lib\site-packages\flask\app.py", line 2073, in wsgi_app
    response = self.full_dispatch_request()
  File "C:\Users\itsvi\Desktop\Project1\venv\lib\site-packages\flask\app.py", line 1518, in full_dispatch_request
    rv = self.handle_user_exception(e)
  File "C:\Users\itsvi\Desktop\Project1\venv\lib\site-packages\flask\app.py", line 1516, in full_dispatch_request
    rv = self.dispatch_request()
  File "C:\Users\itsvi\Desktop\Project1\venv\lib\site-packages\flask\app.py", line 1502, in dispatch_request
    return self.ensure_sync(self.view_functions[rule.endpoint])(**req.view_args)
  File "C:\Users\itsvi\Desktop\Project1\main.py", line 40, in get_employee_by_id
    result = employee_service.service_get_employee_info(user)
  File "C:\Users\itsvi\Desktop\Project1\service_layer\service_imp\employee_postgres_service.py", line 15, in service_get_employee_info
    employee_list = self.employee_dao.get_all_employees()
  File "C:\Users\itsvi\Desktop\Project1\data_access_layer\dao_imp\employee_imp_dao.py", line 24, in get_all_employees
    cursor.execute(sql)
  File "C:\Users\itsvi\Desktop\Project1\venv\lib\site-packages\psycopg\cursor.py", line 561, in execute
    raise ex.with_traceback(None)
psycopg.errors.InFailedSqlTransaction: current transaction is aborted, commands ignored until end of transaction block
2021-12-23 06:35:36,786 INFO 127.0.0.1 - - [23/Dec/2021 06:35:36] "[35m[1mGET /employee/e1 HTTP/1.1[0m" 500 -
2021-12-23 06:35:37,596 ERROR Exception on /employee/e1 [GET]
Traceback (most recent call last):
  File "C:\Users\itsvi\Desktop\Project1\venv\lib\site-packages\flask\app.py", line 2073, in wsgi_app
    response = self.full_dispatch_request()
  File "C:\Users\itsvi\Desktop\Project1\venv\lib\site-packages\flask\app.py", line 1518, in full_dispatch_request
    rv = self.handle_user_exception(e)
  File "C:\Users\itsvi\Desktop\Project1\venv\lib\site-packages\flask\app.py", line 1516, in full_dispatch_request
    rv = self.dispatch_request()
  File "C:\Users\itsvi\Desktop\Project1\venv\lib\site-packages\flask\app.py", line 1502, in dispatch_request
    return self.ensure_sync(self.view_functions[rule.endpoint])(**req.view_args)
  File "C:\Users\itsvi\Desktop\Project1\main.py", line 40, in get_employee_by_id
    result = employee_service.service_get_employee_info(user)
  File "C:\Users\itsvi\Desktop\Project1\service_layer\service_imp\employee_postgres_service.py", line 15, in service_get_employee_info
    employee_list = self.employee_dao.get_all_employees()
  File "C:\Users\itsvi\Desktop\Project1\data_access_layer\dao_imp\employee_imp_dao.py", line 24, in get_all_employees
    cursor.execute(sql)
  File "C:\Users\itsvi\Desktop\Project1\venv\lib\site-packages\psycopg\cursor.py", line 561, in execute
    raise ex.with_traceback(None)
psycopg.errors.InFailedSqlTransaction: current transaction is aborted, commands ignored until end of transaction block
2021-12-23 06:35:37,597 INFO 127.0.0.1 - - [23/Dec/2021 06:35:37] "[35m[1mGET /employee/e1 HTTP/1.1[0m" 500 -
2021-12-23 06:35:37,888 ERROR Exception on /employee/e1 [GET]
Traceback (most recent call last):
  File "C:\Users\itsvi\Desktop\Project1\venv\lib\site-packages\flask\app.py", line 2073, in wsgi_app
    response = self.full_dispatch_request()
  File "C:\Users\itsvi\Desktop\Project1\venv\lib\site-packages\flask\app.py", line 1518, in full_dispatch_request
    rv = self.handle_user_exception(e)
  File "C:\Users\itsvi\Desktop\Project1\venv\lib\site-packages\flask\app.py", line 1516, in full_dispatch_request
    rv = self.dispatch_request()
  File "C:\Users\itsvi\Desktop\Project1\venv\lib\site-packages\flask\app.py", line 1502, in dispatch_request
    return self.ensure_sync(self.view_functions[rule.endpoint])(**req.view_args)
  File "C:\Users\itsvi\Desktop\Project1\main.py", line 40, in get_employee_by_id
    result = employee_service.service_get_employee_info(user)
  File "C:\Users\itsvi\Desktop\Project1\service_layer\service_imp\employee_postgres_service.py", line 15, in service_get_employee_info
    employee_list = self.employee_dao.get_all_employees()
  File "C:\Users\itsvi\Desktop\Project1\data_access_layer\dao_imp\employee_imp_dao.py", line 24, in get_all_employees
    cursor.execute(sql)
  File "C:\Users\itsvi\Desktop\Project1\venv\lib\site-packages\psycopg\cursor.py", line 561, in execute
    raise ex.with_traceback(None)
psycopg.errors.InFailedSqlTransaction: current transaction is aborted, commands ignored until end of transaction block
2021-12-23 06:35:37,889 INFO 127.0.0.1 - - [23/Dec/2021 06:35:37] "[35m[1mGET /employee/e1 HTTP/1.1[0m" 500 -
2021-12-23 06:35:46,372 ERROR Exception on /employee/e3 [GET]
Traceback (most recent call last):
  File "C:\Users\itsvi\Desktop\Project1\venv\lib\site-packages\flask\app.py", line 2073, in wsgi_app
    response = self.full_dispatch_request()
  File "C:\Users\itsvi\Desktop\Project1\venv\lib\site-packages\flask\app.py", line 1518, in full_dispatch_request
    rv = self.handle_user_exception(e)
  File "C:\Users\itsvi\Desktop\Project1\venv\lib\site-packages\flask\app.py", line 1516, in full_dispatch_request
    rv = self.dispatch_request()
  File "C:\Users\itsvi\Desktop\Project1\venv\lib\site-packages\flask\app.py", line 1502, in dispatch_request
    return self.ensure_sync(self.view_functions[rule.endpoint])(**req.view_args)
  File "C:\Users\itsvi\Desktop\Project1\main.py", line 40, in get_employee_by_id
    result = employee_service.service_get_employee_info(user)
  File "C:\Users\itsvi\Desktop\Project1\service_layer\service_imp\employee_postgres_service.py", line 15, in service_get_employee_info
    employee_list = self.employee_dao.get_all_employees()
  File "C:\Users\itsvi\Desktop\Project1\data_access_layer\dao_imp\employee_imp_dao.py", line 24, in get_all_employees
    cursor.execute(sql)
  File "C:\Users\itsvi\Desktop\Project1\venv\lib\site-packages\psycopg\cursor.py", line 561, in execute
    raise ex.with_traceback(None)
psycopg.errors.InFailedSqlTransaction: current transaction is aborted, commands ignored until end of transaction block
2021-12-23 06:35:46,373 INFO 127.0.0.1 - - [23/Dec/2021 06:35:46] "[35m[1mGET /employee/e3 HTTP/1.1[0m" 500 -
2021-12-23 06:35:47,215 ERROR Exception on /employee/e3 [GET]
Traceback (most recent call last):
  File "C:\Users\itsvi\Desktop\Project1\venv\lib\site-packages\flask\app.py", line 2073, in wsgi_app
    response = self.full_dispatch_request()
  File "C:\Users\itsvi\Desktop\Project1\venv\lib\site-packages\flask\app.py", line 1518, in full_dispatch_request
    rv = self.handle_user_exception(e)
  File "C:\Users\itsvi\Desktop\Project1\venv\lib\site-packages\flask\app.py", line 1516, in full_dispatch_request
    rv = self.dispatch_request()
  File "C:\Users\itsvi\Desktop\Project1\venv\lib\site-packages\flask\app.py", line 1502, in dispatch_request
    return self.ensure_sync(self.view_functions[rule.endpoint])(**req.view_args)
  File "C:\Users\itsvi\Desktop\Project1\main.py", line 40, in get_employee_by_id
    result = employee_service.service_get_employee_info(user)
  File "C:\Users\itsvi\Desktop\Project1\service_layer\service_imp\employee_postgres_service.py", line 15, in service_get_employee_info
    employee_list = self.employee_dao.get_all_employees()
  File "C:\Users\itsvi\Desktop\Project1\data_access_layer\dao_imp\employee_imp_dao.py", line 24, in get_all_employees
    cursor.execute(sql)
  File "C:\Users\itsvi\Desktop\Project1\venv\lib\site-packages\psycopg\cursor.py", line 561, in execute
    raise ex.with_traceback(None)
psycopg.errors.InFailedSqlTransaction: current transaction is aborted, commands ignored until end of transaction block
2021-12-23 06:35:47,215 INFO 127.0.0.1 - - [23/Dec/2021 06:35:47] "[35m[1mGET /employee/e3 HTTP/1.1[0m" 500 -
2021-12-23 06:35:47,939 ERROR Exception on /employee/e3 [GET]
Traceback (most recent call last):
  File "C:\Users\itsvi\Desktop\Project1\venv\lib\site-packages\flask\app.py", line 2073, in wsgi_app
    response = self.full_dispatch_request()
  File "C:\Users\itsvi\Desktop\Project1\venv\lib\site-packages\flask\app.py", line 1518, in full_dispatch_request
    rv = self.handle_user_exception(e)
  File "C:\Users\itsvi\Desktop\Project1\venv\lib\site-packages\flask\app.py", line 1516, in full_dispatch_request
    rv = self.dispatch_request()
  File "C:\Users\itsvi\Desktop\Project1\venv\lib\site-packages\flask\app.py", line 1502, in dispatch_request
    return self.ensure_sync(self.view_functions[rule.endpoint])(**req.view_args)
  File "C:\Users\itsvi\Desktop\Project1\main.py", line 40, in get_employee_by_id
    result = employee_service.service_get_employee_info(user)
  File "C:\Users\itsvi\Desktop\Project1\service_layer\service_imp\employee_postgres_service.py", line 15, in service_get_employee_info
    employee_list = self.employee_dao.get_all_employees()
  File "C:\Users\itsvi\Desktop\Project1\data_access_layer\dao_imp\employee_imp_dao.py", line 24, in get_all_employees
    cursor.execute(sql)
  File "C:\Users\itsvi\Desktop\Project1\venv\lib\site-packages\psycopg\cursor.py", line 561, in execute
    raise ex.with_traceback(None)
psycopg.errors.InFailedSqlTransaction: current transaction is aborted, commands ignored until end of transaction block
2021-12-23 06:35:47,940 INFO 127.0.0.1 - - [23/Dec/2021 06:35:47] "[35m[1mGET /employee/e3 HTTP/1.1[0m" 500 -
2021-12-23 06:35:48,939 ERROR Exception on /employee/e3 [GET]
Traceback (most recent call last):
  File "C:\Users\itsvi\Desktop\Project1\venv\lib\site-packages\flask\app.py", line 2073, in wsgi_app
    response = self.full_dispatch_request()
  File "C:\Users\itsvi\Desktop\Project1\venv\lib\site-packages\flask\app.py", line 1518, in full_dispatch_request
    rv = self.handle_user_exception(e)
  File "C:\Users\itsvi\Desktop\Project1\venv\lib\site-packages\flask\app.py", line 1516, in full_dispatch_request
    rv = self.dispatch_request()
  File "C:\Users\itsvi\Desktop\Project1\venv\lib\site-packages\flask\app.py", line 1502, in dispatch_request
    return self.ensure_sync(self.view_functions[rule.endpoint])(**req.view_args)
  File "C:\Users\itsvi\Desktop\Project1\main.py", line 40, in get_employee_by_id
    result = employee_service.service_get_employee_info(user)
  File "C:\Users\itsvi\Desktop\Project1\service_layer\service_imp\employee_postgres_service.py", line 15, in service_get_employee_info
    employee_list = self.employee_dao.get_all_employees()
  File "C:\Users\itsvi\Desktop\Project1\data_access_layer\dao_imp\employee_imp_dao.py", line 24, in get_all_employees
    cursor.execute(sql)
  File "C:\Users\itsvi\Desktop\Project1\venv\lib\site-packages\psycopg\cursor.py", line 561, in execute
    raise ex.with_traceback(None)
psycopg.errors.InFailedSqlTransaction: current transaction is aborted, commands ignored until end of transaction block
2021-12-23 06:35:48,940 INFO 127.0.0.1 - - [23/Dec/2021 06:35:48] "[35m[1mGET /employee/e3 HTTP/1.1[0m" 500 -
2021-12-23 06:38:29,279 ERROR Exception on /employee/e2 [GET]
Traceback (most recent call last):
  File "C:\Users\itsvi\Desktop\Project1\venv\lib\site-packages\flask\app.py", line 2073, in wsgi_app
    response = self.full_dispatch_request()
  File "C:\Users\itsvi\Desktop\Project1\venv\lib\site-packages\flask\app.py", line 1518, in full_dispatch_request
    rv = self.handle_user_exception(e)
  File "C:\Users\itsvi\Desktop\Project1\venv\lib\site-packages\flask\app.py", line 1516, in full_dispatch_request
    rv = self.dispatch_request()
  File "C:\Users\itsvi\Desktop\Project1\venv\lib\site-packages\flask\app.py", line 1502, in dispatch_request
    return self.ensure_sync(self.view_functions[rule.endpoint])(**req.view_args)
  File "C:\Users\itsvi\Desktop\Project1\main.py", line 40, in get_employee_by_id
    result = employee_service.service_get_employee_info(user)
  File "C:\Users\itsvi\Desktop\Project1\service_layer\service_imp\employee_postgres_service.py", line 15, in service_get_employee_info
    employee_list = self.employee_dao.get_all_employees()
  File "C:\Users\itsvi\Desktop\Project1\data_access_layer\dao_imp\employee_imp_dao.py", line 24, in get_all_employees
    cursor.execute(sql)
  File "C:\Users\itsvi\Desktop\Project1\venv\lib\site-packages\psycopg\cursor.py", line 561, in execute
    raise ex.with_traceback(None)
psycopg.errors.InFailedSqlTransaction: current transaction is aborted, commands ignored until end of transaction block
2021-12-23 06:38:29,279 INFO 127.0.0.1 - - [23/Dec/2021 06:38:29] "[35m[1mGET /employee/e2 HTTP/1.1[0m" 500 -
2021-12-23 06:38:30,555 ERROR Exception on /employee/e2 [GET]
Traceback (most recent call last):
  File "C:\Users\itsvi\Desktop\Project1\venv\lib\site-packages\flask\app.py", line 2073, in wsgi_app
    response = self.full_dispatch_request()
  File "C:\Users\itsvi\Desktop\Project1\venv\lib\site-packages\flask\app.py", line 1518, in full_dispatch_request
    rv = self.handle_user_exception(e)
  File "C:\Users\itsvi\Desktop\Project1\venv\lib\site-packages\flask\app.py", line 1516, in full_dispatch_request
    rv = self.dispatch_request()
  File "C:\Users\itsvi\Desktop\Project1\venv\lib\site-packages\flask\app.py", line 1502, in dispatch_request
    return self.ensure_sync(self.view_functions[rule.endpoint])(**req.view_args)
  File "C:\Users\itsvi\Desktop\Project1\main.py", line 40, in get_employee_by_id
    result = employee_service.service_get_employee_info(user)
  File "C:\Users\itsvi\Desktop\Project1\service_layer\service_imp\employee_postgres_service.py", line 15, in service_get_employee_info
    employee_list = self.employee_dao.get_all_employees()
  File "C:\Users\itsvi\Desktop\Project1\data_access_layer\dao_imp\employee_imp_dao.py", line 24, in get_all_employees
    cursor.execute(sql)
  File "C:\Users\itsvi\Desktop\Project1\venv\lib\site-packages\psycopg\cursor.py", line 561, in execute
    raise ex.with_traceback(None)
psycopg.errors.InFailedSqlTransaction: current transaction is aborted, commands ignored until end of transaction block
2021-12-23 06:38:30,556 INFO 127.0.0.1 - - [23/Dec/2021 06:38:30] "[35m[1mGET /employee/e2 HTTP/1.1[0m" 500 -
2021-12-23 06:38:34,721 INFO  * Running on http://127.0.0.1:5000/ (Press CTRL+C to quit)
2021-12-23 06:38:38,795 ERROR Exception on /employee/e2 [GET]
Traceback (most recent call last):
  File "C:\Users\itsvi\Desktop\Project1\venv\lib\site-packages\flask\app.py", line 2073, in wsgi_app
    response = self.full_dispatch_request()
  File "C:\Users\itsvi\Desktop\Project1\venv\lib\site-packages\flask\app.py", line 1518, in full_dispatch_request
    rv = self.handle_user_exception(e)
  File "C:\Users\itsvi\Desktop\Project1\venv\lib\site-packages\flask\app.py", line 1516, in full_dispatch_request
    rv = self.dispatch_request()
  File "C:\Users\itsvi\Desktop\Project1\venv\lib\site-packages\flask\app.py", line 1502, in dispatch_request
    return self.ensure_sync(self.view_functions[rule.endpoint])(**req.view_args)
  File "C:\Users\itsvi\Desktop\Project1\main.py", line 40, in get_employee_by_id
    result = employee_service.service_get_employee_info(user)
  File "C:\Users\itsvi\Desktop\Project1\service_layer\service_imp\employee_postgres_service.py", line 18, in service_get_employee_info
    return self.employee_dao.get_employee_info(user)
  File "C:\Users\itsvi\Desktop\Project1\data_access_layer\dao_imp\employee_imp_dao.py", line 16, in get_employee_info
    cursor.execute(sql, [employee_id])
  File "C:\Users\itsvi\Desktop\Project1\venv\lib\site-packages\psycopg\cursor.py", line 561, in execute
    raise ex.with_traceback(None)
psycopg.errors.InvalidTextRepresentation: invalid input syntax for integer: "e2"
2021-12-23 06:38:38,798 INFO 127.0.0.1 - - [23/Dec/2021 06:38:38] "[35m[1mGET /employee/e2 HTTP/1.1[0m" 500 -
2021-12-23 06:40:19,478 ERROR Exception on /employee [GET]
Traceback (most recent call last):
  File "C:\Users\itsvi\Desktop\Project1\venv\lib\site-packages\flask\app.py", line 2073, in wsgi_app
    response = self.full_dispatch_request()
  File "C:\Users\itsvi\Desktop\Project1\venv\lib\site-packages\flask\app.py", line 1518, in full_dispatch_request
    rv = self.handle_user_exception(e)
  File "C:\Users\itsvi\Desktop\Project1\venv\lib\site-packages\flask\app.py", line 1516, in full_dispatch_request
    rv = self.dispatch_request()
  File "C:\Users\itsvi\Desktop\Project1\venv\lib\site-packages\flask\app.py", line 1502, in dispatch_request
    return self.ensure_sync(self.view_functions[rule.endpoint])(**req.view_args)
  File "C:\Users\itsvi\Desktop\Project1\main.py", line 52, in get_all_employees
    employees = employee_service.service_get_all_employee()
  File "C:\Users\itsvi\Desktop\Project1\service_layer\service_imp\employee_postgres_service.py", line 22, in service_get_all_employee
    all_employee = self.employee_dao.get_all_employees()
  File "C:\Users\itsvi\Desktop\Project1\data_access_layer\dao_imp\employee_imp_dao.py", line 24, in get_all_employees
    cursor.execute(sql)
  File "C:\Users\itsvi\Desktop\Project1\venv\lib\site-packages\psycopg\cursor.py", line 561, in execute
    raise ex.with_traceback(None)
psycopg.errors.InFailedSqlTransaction: current transaction is aborted, commands ignored until end of transaction block
2021-12-23 06:40:19,480 INFO 127.0.0.1 - - [23/Dec/2021 06:40:19] "[35m[1mGET /employee HTTP/1.1[0m" 500 -
2021-12-23 06:40:27,039 ERROR Exception on /employee [GET]
Traceback (most recent call last):
  File "C:\Users\itsvi\Desktop\Project1\venv\lib\site-packages\flask\app.py", line 2073, in wsgi_app
    response = self.full_dispatch_request()
  File "C:\Users\itsvi\Desktop\Project1\venv\lib\site-packages\flask\app.py", line 1518, in full_dispatch_request
    rv = self.handle_user_exception(e)
  File "C:\Users\itsvi\Desktop\Project1\venv\lib\site-packages\flask\app.py", line 1516, in full_dispatch_request
    rv = self.dispatch_request()
  File "C:\Users\itsvi\Desktop\Project1\venv\lib\site-packages\flask\app.py", line 1502, in dispatch_request
    return self.ensure_sync(self.view_functions[rule.endpoint])(**req.view_args)
  File "C:\Users\itsvi\Desktop\Project1\main.py", line 52, in get_all_employees
    employees = employee_service.service_get_all_employee()
  File "C:\Users\itsvi\Desktop\Project1\service_layer\service_imp\employee_postgres_service.py", line 22, in service_get_all_employee
    all_employee = self.employee_dao.get_all_employees()
  File "C:\Users\itsvi\Desktop\Project1\data_access_layer\dao_imp\employee_imp_dao.py", line 24, in get_all_employees
    cursor.execute(sql)
  File "C:\Users\itsvi\Desktop\Project1\venv\lib\site-packages\psycopg\cursor.py", line 561, in execute
    raise ex.with_traceback(None)
psycopg.errors.InFailedSqlTransaction: current transaction is aborted, commands ignored until end of transaction block
2021-12-23 06:40:27,040 INFO 127.0.0.1 - - [23/Dec/2021 06:40:27] "[35m[1mGET /employee HTTP/1.1[0m" 500 -
2021-12-23 06:40:30,087 INFO  * Running on http://127.0.0.1:5000/ (Press CTRL+C to quit)
2021-12-23 06:40:31,955 INFO 127.0.0.1 - - [23/Dec/2021 06:40:31] "GET /employee HTTP/1.1" 200 -
2021-12-23 06:42:59,441 INFO 127.0.0.1 - - [23/Dec/2021 06:42:59] "GET /employee/reimbursement/2 HTTP/1.1" 200 -
2021-12-23 06:43:03,236 INFO 127.0.0.1 - - [23/Dec/2021 06:43:03] "GET /employee/reimbursement/3 HTTP/1.1" 200 -
2021-12-23 06:43:44,642 INFO 127.0.0.1 - - [23/Dec/2021 06:43:44] "POST /reimbursement HTTP/1.1" 200 -
2021-12-23 06:46:30,336 INFO  * Running on http://127.0.0.1:5000/ (Press CTRL+C to quit)
2021-12-23 06:46:40,734 INFO 127.0.0.1 - - [23/Dec/2021 06:46:40] "POST /manager/login HTTP/1.1" 200 -
2021-12-23 06:47:17,141 INFO 127.0.0.1 - - [23/Dec/2021 06:47:17] "[31m[1mPOST /manager/login HTTP/1.1[0m" 400 -
2021-12-23 06:47:27,514 INFO 127.0.0.1 - - [23/Dec/2021 06:47:27] "POST /manager/login HTTP/1.1" 200 -
2021-12-23 06:47:40,975 ERROR Exception on /manager/login [POST]
Traceback (most recent call last):
  File "C:\Users\itsvi\Desktop\Project1\venv\lib\site-packages\flask\app.py", line 2073, in wsgi_app
    response = self.full_dispatch_request()
  File "C:\Users\itsvi\Desktop\Project1\venv\lib\site-packages\flask\app.py", line 1518, in full_dispatch_request
    rv = self.handle_user_exception(e)
  File "C:\Users\itsvi\Desktop\Project1\venv\lib\site-packages\flask\app.py", line 1516, in full_dispatch_request
    rv = self.dispatch_request()
  File "C:\Users\itsvi\Desktop\Project1\venv\lib\site-packages\flask\app.py", line 1502, in dispatch_request
    return self.ensure_sync(self.view_functions[rule.endpoint])(**req.view_args)
  File "C:\Users\itsvi\Desktop\Project1\main.py", line 188, in service_get_login_for_manager
    return_manager: Manager = manager_service.service_get_login_for_manager(manager_id, manager_passcode)
  File "C:\Users\itsvi\Desktop\Project1\service_layer\service_imp\manager_postgres_service.py", line 33, in service_get_login_for_manager
    return self.manager_dao.get_login_for_manager(user, passcode)
  File "C:\Users\itsvi\Desktop\Project1\data_access_layer\dao_imp\manager_imp_dao.py", line 46, in get_login_for_manager
    this_manager = Manager(*manager_record)
TypeError: entities.manager.Manager() argument after * must be an iterable, not NoneType
2021-12-23 06:47:40,976 INFO 127.0.0.1 - - [23/Dec/2021 06:47:40] "[35m[1mPOST /manager/login HTTP/1.1[0m" 500 -
2021-12-23 06:47:45,989 INFO  * Running on http://127.0.0.1:5000/ (Press CTRL+C to quit)
2021-12-23 06:47:53,421 ERROR Exception on /manager/login [POST]
Traceback (most recent call last):
  File "C:\Users\itsvi\Desktop\Project1\venv\lib\site-packages\flask\app.py", line 2073, in wsgi_app
    response = self.full_dispatch_request()
  File "C:\Users\itsvi\Desktop\Project1\venv\lib\site-packages\flask\app.py", line 1518, in full_dispatch_request
    rv = self.handle_user_exception(e)
  File "C:\Users\itsvi\Desktop\Project1\venv\lib\site-packages\flask\app.py", line 1516, in full_dispatch_request
    rv = self.dispatch_request()
  File "C:\Users\itsvi\Desktop\Project1\venv\lib\site-packages\flask\app.py", line 1502, in dispatch_request
    return self.ensure_sync(self.view_functions[rule.endpoint])(**req.view_args)
  File "C:\Users\itsvi\Desktop\Project1\main.py", line 188, in service_get_login_for_manager
    return_manager: Manager = manager_service.service_get_login_for_manager(manager_id, manager_passcode)
  File "C:\Users\itsvi\Desktop\Project1\service_layer\service_imp\manager_postgres_service.py", line 33, in service_get_login_for_manager
    return self.manager_dao.get_login_for_manager(user, passcode)
  File "C:\Users\itsvi\Desktop\Project1\data_access_layer\dao_imp\manager_imp_dao.py", line 46, in get_login_for_manager
    this_manager = Manager(*manager_record)
TypeError: entities.manager.Manager() argument after * must be an iterable, not NoneType
2021-12-23 06:47:53,424 INFO 127.0.0.1 - - [23/Dec/2021 06:47:53] "[35m[1mPOST /manager/login HTTP/1.1[0m" 500 -
2021-12-23 06:48:02,972 ERROR Exception on /manager/login [POST]
Traceback (most recent call last):
  File "C:\Users\itsvi\Desktop\Project1\venv\lib\site-packages\flask\app.py", line 2073, in wsgi_app
    response = self.full_dispatch_request()
  File "C:\Users\itsvi\Desktop\Project1\venv\lib\site-packages\flask\app.py", line 1518, in full_dispatch_request
    rv = self.handle_user_exception(e)
  File "C:\Users\itsvi\Desktop\Project1\venv\lib\site-packages\flask\app.py", line 1516, in full_dispatch_request
    rv = self.dispatch_request()
  File "C:\Users\itsvi\Desktop\Project1\venv\lib\site-packages\flask\app.py", line 1502, in dispatch_request
    return self.ensure_sync(self.view_functions[rule.endpoint])(**req.view_args)
  File "C:\Users\itsvi\Desktop\Project1\main.py", line 188, in service_get_login_for_manager
    return_manager: Manager = manager_service.service_get_login_for_manager(manager_id, manager_passcode)
  File "C:\Users\itsvi\Desktop\Project1\service_layer\service_imp\manager_postgres_service.py", line 33, in service_get_login_for_manager
    return self.manager_dao.get_login_for_manager(user, passcode)
  File "C:\Users\itsvi\Desktop\Project1\data_access_layer\dao_imp\manager_imp_dao.py", line 46, in get_login_for_manager
    this_manager = Manager(*manager_record)
TypeError: entities.manager.Manager() argument after * must be an iterable, not NoneType
2021-12-23 06:48:02,974 INFO 127.0.0.1 - - [23/Dec/2021 06:48:02] "[35m[1mPOST /manager/login HTTP/1.1[0m" 500 -
2021-12-23 06:48:04,228 ERROR Exception on /manager/login [POST]
Traceback (most recent call last):
  File "C:\Users\itsvi\Desktop\Project1\venv\lib\site-packages\flask\app.py", line 2073, in wsgi_app
    response = self.full_dispatch_request()
  File "C:\Users\itsvi\Desktop\Project1\venv\lib\site-packages\flask\app.py", line 1518, in full_dispatch_request
    rv = self.handle_user_exception(e)
  File "C:\Users\itsvi\Desktop\Project1\venv\lib\site-packages\flask\app.py", line 1516, in full_dispatch_request
    rv = self.dispatch_request()
  File "C:\Users\itsvi\Desktop\Project1\venv\lib\site-packages\flask\app.py", line 1502, in dispatch_request
    return self.ensure_sync(self.view_functions[rule.endpoint])(**req.view_args)
  File "C:\Users\itsvi\Desktop\Project1\main.py", line 188, in service_get_login_for_manager
    return_manager: Manager = manager_service.service_get_login_for_manager(manager_id, manager_passcode)
  File "C:\Users\itsvi\Desktop\Project1\service_layer\service_imp\manager_postgres_service.py", line 33, in service_get_login_for_manager
    return self.manager_dao.get_login_for_manager(user, passcode)
  File "C:\Users\itsvi\Desktop\Project1\data_access_layer\dao_imp\manager_imp_dao.py", line 46, in get_login_for_manager
    this_manager = Manager(*manager_record)
TypeError: entities.manager.Manager() argument after * must be an iterable, not NoneType
2021-12-23 06:48:04,229 INFO 127.0.0.1 - - [23/Dec/2021 06:48:04] "[35m[1mPOST /manager/login HTTP/1.1[0m" 500 -
2021-12-23 06:48:14,937 INFO 127.0.0.1 - - [23/Dec/2021 06:48:14] "POST /manager/login HTTP/1.1" 200 -
2021-12-23 06:51:48,319 INFO 127.0.0.1 - - [23/Dec/2021 06:51:48] "POST /employee/login HTTP/1.1" 200 -
2021-12-23 06:51:56,938 ERROR Exception on /employee/login [POST]
Traceback (most recent call last):
  File "C:\Users\itsvi\Desktop\Project1\venv\lib\site-packages\flask\app.py", line 2073, in wsgi_app
    response = self.full_dispatch_request()
  File "C:\Users\itsvi\Desktop\Project1\venv\lib\site-packages\flask\app.py", line 1518, in full_dispatch_request
    rv = self.handle_user_exception(e)
  File "C:\Users\itsvi\Desktop\Project1\venv\lib\site-packages\flask\app.py", line 1516, in full_dispatch_request
    rv = self.dispatch_request()
  File "C:\Users\itsvi\Desktop\Project1\venv\lib\site-packages\flask\app.py", line 1502, in dispatch_request
    return self.ensure_sync(self.view_functions[rule.endpoint])(**req.view_args)
  File "C:\Users\itsvi\Desktop\Project1\main.py", line 65, in service_get_login_for_employee
    employee_id = result["employeeId"]
KeyError: 'employeeId'
2021-12-23 06:51:56,938 INFO 127.0.0.1 - - [23/Dec/2021 06:51:56] "[35m[1mPOST /employee/login HTTP/1.1[0m" 500 -
2021-12-23 06:51:58,830 ERROR Exception on /employee/login [POST]
Traceback (most recent call last):
  File "C:\Users\itsvi\Desktop\Project1\venv\lib\site-packages\flask\app.py", line 2073, in wsgi_app
    response = self.full_dispatch_request()
  File "C:\Users\itsvi\Desktop\Project1\venv\lib\site-packages\flask\app.py", line 1518, in full_dispatch_request
    rv = self.handle_user_exception(e)
  File "C:\Users\itsvi\Desktop\Project1\venv\lib\site-packages\flask\app.py", line 1516, in full_dispatch_request
    rv = self.dispatch_request()
  File "C:\Users\itsvi\Desktop\Project1\venv\lib\site-packages\flask\app.py", line 1502, in dispatch_request
    return self.ensure_sync(self.view_functions[rule.endpoint])(**req.view_args)
  File "C:\Users\itsvi\Desktop\Project1\main.py", line 65, in service_get_login_for_employee
    employee_id = result["employeeId"]
KeyError: 'employeeId'
2021-12-23 06:51:58,831 INFO 127.0.0.1 - - [23/Dec/2021 06:51:58] "[35m[1mPOST /employee/login HTTP/1.1[0m" 500 -
2021-12-23 06:52:04,122 ERROR Exception on /employee/login [POST]
Traceback (most recent call last):
  File "C:\Users\itsvi\Desktop\Project1\venv\lib\site-packages\flask\app.py", line 2073, in wsgi_app
    response = self.full_dispatch_request()
  File "C:\Users\itsvi\Desktop\Project1\venv\lib\site-packages\flask\app.py", line 1518, in full_dispatch_request
    rv = self.handle_user_exception(e)
  File "C:\Users\itsvi\Desktop\Project1\venv\lib\site-packages\flask\app.py", line 1516, in full_dispatch_request
    rv = self.dispatch_request()
  File "C:\Users\itsvi\Desktop\Project1\venv\lib\site-packages\flask\app.py", line 1502, in dispatch_request
    return self.ensure_sync(self.view_functions[rule.endpoint])(**req.view_args)
  File "C:\Users\itsvi\Desktop\Project1\main.py", line 65, in service_get_login_for_employee
    employee_id = result["employeeId"]
KeyError: 'employeeId'
2021-12-23 06:52:04,122 INFO 127.0.0.1 - - [23/Dec/2021 06:52:04] "[35m[1mPOST /employee/login HTTP/1.1[0m" 500 -
2021-12-23 06:52:12,426 ERROR Exception on /employee/login [POST]
Traceback (most recent call last):
  File "C:\Users\itsvi\Desktop\Project1\venv\lib\site-packages\flask\app.py", line 2073, in wsgi_app
    response = self.full_dispatch_request()
  File "C:\Users\itsvi\Desktop\Project1\venv\lib\site-packages\flask\app.py", line 1518, in full_dispatch_request
    rv = self.handle_user_exception(e)
  File "C:\Users\itsvi\Desktop\Project1\venv\lib\site-packages\flask\app.py", line 1516, in full_dispatch_request
    rv = self.dispatch_request()
  File "C:\Users\itsvi\Desktop\Project1\venv\lib\site-packages\flask\app.py", line 1502, in dispatch_request
    return self.ensure_sync(self.view_functions[rule.endpoint])(**req.view_args)
  File "C:\Users\itsvi\Desktop\Project1\main.py", line 65, in service_get_login_for_employee
    employee_id = result["employeeId"]
KeyError: 'employeeId'
2021-12-23 06:52:12,427 INFO 127.0.0.1 - - [23/Dec/2021 06:52:12] "[35m[1mPOST /employee/login HTTP/1.1[0m" 500 -
2021-12-23 06:52:13,350 ERROR Exception on /employee/login [POST]
Traceback (most recent call last):
  File "C:\Users\itsvi\Desktop\Project1\venv\lib\site-packages\flask\app.py", line 2073, in wsgi_app
    response = self.full_dispatch_request()
  File "C:\Users\itsvi\Desktop\Project1\venv\lib\site-packages\flask\app.py", line 1518, in full_dispatch_request
    rv = self.handle_user_exception(e)
  File "C:\Users\itsvi\Desktop\Project1\venv\lib\site-packages\flask\app.py", line 1516, in full_dispatch_request
    rv = self.dispatch_request()
  File "C:\Users\itsvi\Desktop\Project1\venv\lib\site-packages\flask\app.py", line 1502, in dispatch_request
    return self.ensure_sync(self.view_functions[rule.endpoint])(**req.view_args)
  File "C:\Users\itsvi\Desktop\Project1\main.py", line 65, in service_get_login_for_employee
    employee_id = result["employeeId"]
KeyError: 'employeeId'
2021-12-23 06:52:13,351 INFO 127.0.0.1 - - [23/Dec/2021 06:52:13] "[35m[1mPOST /employee/login HTTP/1.1[0m" 500 -
2021-12-23 06:52:16,812 INFO 127.0.0.1 - - [23/Dec/2021 06:52:16] "POST /employee/login HTTP/1.1" 200 -
2021-12-23 06:55:43,143 ERROR Exception on /employee/login [POST]
Traceback (most recent call last):
  File "C:\Users\itsvi\Desktop\Project1\venv\lib\site-packages\flask\app.py", line 2073, in wsgi_app
    response = self.full_dispatch_request()
  File "C:\Users\itsvi\Desktop\Project1\venv\lib\site-packages\flask\app.py", line 1518, in full_dispatch_request
    rv = self.handle_user_exception(e)
  File "C:\Users\itsvi\Desktop\Project1\venv\lib\site-packages\flask\app.py", line 1516, in full_dispatch_request
    rv = self.dispatch_request()
  File "C:\Users\itsvi\Desktop\Project1\venv\lib\site-packages\flask\app.py", line 1502, in dispatch_request
    return self.ensure_sync(self.view_functions[rule.endpoint])(**req.view_args)
  File "C:\Users\itsvi\Desktop\Project1\main.py", line 65, in service_get_login_for_employee
    employee_id = result["user"]
KeyError: 'employeeId'
2021-12-23 06:55:43,144 INFO 127.0.0.1 - - [23/Dec/2021 06:55:43] "[35m[1mPOST /employee/login HTTP/1.1[0m" 500 -
2021-12-23 06:55:52,301 INFO  * Running on http://127.0.0.1:5000/ (Press CTRL+C to quit)
2021-12-23 06:56:01,251 INFO 127.0.0.1 - - [23/Dec/2021 06:56:01] "POST /employee/login HTTP/1.1" 200 -
2021-12-23 06:56:10,335 INFO 127.0.0.1 - - [23/Dec/2021 06:56:10] "POST /employee/login HTTP/1.1" 200 -
2021-12-23 06:59:44,707 INFO 127.0.0.1 - - [23/Dec/2021 06:59:44] "[33mGET /manager HTTP/1.1[0m" 404 -
2021-12-23 06:59:53,225 INFO  * Running on http://127.0.0.1:5000/ (Press CTRL+C to quit)
2021-12-23 06:59:56,945 INFO 127.0.0.1 - - [23/Dec/2021 06:59:56] "GET /manager HTTP/1.1" 200 -
2021-12-23 07:01:06,888 INFO 127.0.0.1 - - [23/Dec/2021 07:01:06] "GET /manager/pending/reimbursement/10 HTTP/1.1" 200 -
2021-12-23 07:03:13,901 INFO 127.0.0.1 - - [23/Dec/2021 07:03:13] "POST /reimbursement HTTP/1.1" 200 -
2021-12-23 07:03:19,555 INFO 127.0.0.1 - - [23/Dec/2021 07:03:19] "POST /reimbursement HTTP/1.1" 200 -
2021-12-23 07:03:24,285 INFO 127.0.0.1 - - [23/Dec/2021 07:03:24] "POST /reimbursement HTTP/1.1" 200 -
2021-12-23 07:04:02,318 ERROR Exception on /manager/pending/reimbursement/54 [GET]
Traceback (most recent call last):
  File "C:\Users\itsvi\Desktop\Project1\venv\lib\site-packages\flask\app.py", line 2073, in wsgi_app
    response = self.full_dispatch_request()
  File "C:\Users\itsvi\Desktop\Project1\venv\lib\site-packages\flask\app.py", line 1518, in full_dispatch_request
    rv = self.handle_user_exception(e)
  File "C:\Users\itsvi\Desktop\Project1\venv\lib\site-packages\flask\app.py", line 1516, in full_dispatch_request
    rv = self.dispatch_request()
  File "C:\Users\itsvi\Desktop\Project1\venv\lib\site-packages\flask\app.py", line 1502, in dispatch_request
    return self.ensure_sync(self.view_functions[rule.endpoint])(**req.view_args)
  File "C:\Users\itsvi\Desktop\Project1\main.py", line 144, in get_all_pending_reimbursement_by_manager_id
    reimbursement_as_reimbursement = reimbursement_service.service_get_all_pending_reimbursement_by_manager_id(
  File "C:\Users\itsvi\Desktop\Project1\service_layer\service_imp\reimbursement_postgres_service.py", line 79, in service_get_all_pending_reimbursement_by_manager_id
    raise ManagerNonexistException("Does not exist.")
custom_exceptions.manager_nonexist_exception.ManagerNonexistException: Does not exist.
2021-12-23 07:04:02,326 INFO 127.0.0.1 - - [23/Dec/2021 07:04:02] "[35m[1mGET /manager/pending/reimbursement/54 HTTP/1.1[0m" 500 -
2021-12-23 07:04:15,956 INFO 127.0.0.1 - - [23/Dec/2021 07:04:15] "GET /manager/pending/reimbursement/10 HTTP/1.1" 200 -
2021-12-23 07:05:07,653 INFO 127.0.0.1 - - [23/Dec/2021 07:05:07] "GET /past/reimbursements/3 HTTP/1.1" 200 -
2021-12-23 07:05:11,706 ERROR Exception on /past/reimbursements/4 [GET]
Traceback (most recent call last):
  File "C:\Users\itsvi\Desktop\Project1\venv\lib\site-packages\flask\app.py", line 2073, in wsgi_app
    response = self.full_dispatch_request()
  File "C:\Users\itsvi\Desktop\Project1\venv\lib\site-packages\flask\app.py", line 1518, in full_dispatch_request
    rv = self.handle_user_exception(e)
  File "C:\Users\itsvi\Desktop\Project1\venv\lib\site-packages\flask\app.py", line 1516, in full_dispatch_request
    rv = self.dispatch_request()
  File "C:\Users\itsvi\Desktop\Project1\venv\lib\site-packages\flask\app.py", line 1502, in dispatch_request
    return self.ensure_sync(self.view_functions[rule.endpoint])(**req.view_args)
  File "C:\Users\itsvi\Desktop\Project1\main.py", line 133, in get_all_past_reimbursement_information
    reimbursement_as_reimbursement = reimbursement_service.service_get_past_reimbursement_by_manager_id(
  File "C:\Users\itsvi\Desktop\Project1\service_layer\service_imp\reimbursement_postgres_service.py", line 87, in service_get_past_reimbursement_by_manager_id
    raise ManagerNonexistException("Does not exist.")
custom_exceptions.manager_nonexist_exception.ManagerNonexistException: Does not exist.
2021-12-23 07:05:11,708 INFO 127.0.0.1 - - [23/Dec/2021 07:05:11] "[35m[1mGET /past/reimbursements/4 HTTP/1.1[0m" 500 -
2021-12-23 07:05:17,677 INFO 127.0.0.1 - - [23/Dec/2021 07:05:17] "GET /past/reimbursements/3 HTTP/1.1" 200 -
2021-12-23 07:05:31,264 INFO 127.0.0.1 - - [23/Dec/2021 07:05:31] "GET /past/reimbursements/1 HTTP/1.1" 200 -
2021-12-23 07:05:43,644 INFO 127.0.0.1 - - [23/Dec/2021 07:05:43] "GET /past/reimbursements/2 HTTP/1.1" 200 -
2021-12-23 07:08:26,380 INFO 127.0.0.1 - - [23/Dec/2021 07:08:26] "GET /past/reimbursements/1 HTTP/1.1" 200 -
2021-12-23 07:11:29,512 INFO 127.0.0.1 - - [23/Dec/2021 07:11:29] "PATCH /reimbursement/accept/57 HTTP/1.1" 200 -
2021-12-23 07:11:54,043 INFO 127.0.0.1 - - [23/Dec/2021 07:11:54] "PATCH /reimbursement/accept/57 HTTP/1.1" 200 -
2021-12-23 07:12:32,994 INFO 127.0.0.1 - - [23/Dec/2021 07:12:32] "PATCH /reimbursement/accept/57 HTTP/1.1" 200 -
2021-12-23 07:20:36,223 INFO  * Running on http://127.0.0.1:5000/ (Press CTRL+C to quit)
2021-12-23 07:26:26,744 INFO 127.0.0.1 - - [23/Dec/2021 07:26:26] "OPTIONS /employee/login HTTP/1.1" 200 -
2021-12-23 07:26:27,527 INFO 127.0.0.1 - - [23/Dec/2021 07:26:27] "OPTIONS /employee/login HTTP/1.1" 200 -
2021-12-23 07:26:27,715 INFO 127.0.0.1 - - [23/Dec/2021 07:26:27] "OPTIONS /employee/login HTTP/1.1" 200 -
2021-12-23 07:26:28,190 INFO 127.0.0.1 - - [23/Dec/2021 07:26:28] "OPTIONS /employee/login HTTP/1.1" 200 -
2021-12-23 07:26:28,368 INFO 127.0.0.1 - - [23/Dec/2021 07:26:28] "OPTIONS /employee/login HTTP/1.1" 200 -
2021-12-23 07:26:28,545 INFO 127.0.0.1 - - [23/Dec/2021 07:26:28] "OPTIONS /employee/login HTTP/1.1" 200 -
2021-12-23 07:26:29,279 INFO 127.0.0.1 - - [23/Dec/2021 07:26:29] "OPTIONS /employee/login HTTP/1.1" 200 -
2021-12-23 07:26:29,434 INFO 127.0.0.1 - - [23/Dec/2021 07:26:29] "OPTIONS /employee/login HTTP/1.1" 200 -
2021-12-23 07:26:29,590 INFO 127.0.0.1 - - [23/Dec/2021 07:26:29] "OPTIONS /employee/login HTTP/1.1" 200 -
2021-12-23 07:27:23,719 INFO 127.0.0.1 - - [23/Dec/2021 07:27:23] "[33mGET /reimbursement/approve/null HTTP/1.1[0m" 404 -
2021-12-23 07:27:24,655 INFO 127.0.0.1 - - [23/Dec/2021 07:27:24] "[33mGET /reimbursement/approve/null HTTP/1.1[0m" 404 -
2021-12-23 07:27:24,876 INFO 127.0.0.1 - - [23/Dec/2021 07:27:24] "[33mGET /reimbursement/approve/null HTTP/1.1[0m" 404 -
2021-12-23 07:47:06,296 INFO  * Running on http://127.0.0.1:5000/ (Press CTRL+C to quit)
2021-12-23 07:47:36,214 INFO  * Running on http://127.0.0.1:5000/ (Press CTRL+C to quit)
2021-12-23 08:28:33,295 INFO  * Running on http://127.0.0.1:5000/ (Press CTRL+C to quit)
2021-12-23 08:31:10,638 INFO  * Running on http://127.0.0.1:5000/ (Press CTRL+C to quit)
2021-12-23 09:20:01,658 INFO  * Running on http://127.0.0.1:5000/ (Press CTRL+C to quit)
2021-12-23 09:20:09,855 INFO 127.0.0.1 - - [23/Dec/2021 09:20:09] "POST /employee/login HTTP/1.1" 200 -
2021-12-23 10:21:53,990 INFO  * Running on http://127.0.0.1:5000/ (Press CTRL+C to quit)
2021-12-23 10:23:04,420 INFO 127.0.0.1 - - [23/Dec/2021 10:23:04] "OPTIONS /employee/login HTTP/1.1" 200 -
2021-12-23 10:23:06,513 INFO 127.0.0.1 - - [23/Dec/2021 10:23:06] "OPTIONS /employee/login HTTP/1.1" 200 -
2021-12-23 10:23:15,330 INFO 127.0.0.1 - - [23/Dec/2021 10:23:15] "OPTIONS /employee/login HTTP/1.1" 200 -
2021-12-23 10:23:22,222 INFO 127.0.0.1 - - [23/Dec/2021 10:23:22] "OPTIONS /employee/login HTTP/1.1" 200 -
2021-12-23 10:23:22,762 INFO 127.0.0.1 - - [23/Dec/2021 10:23:22] "OPTIONS /employee/login HTTP/1.1" 200 -
2021-12-23 10:23:23,009 INFO 127.0.0.1 - - [23/Dec/2021 10:23:23] "OPTIONS /employee/login HTTP/1.1" 200 -
2021-12-23 10:25:09,828 INFO 127.0.0.1 - - [23/Dec/2021 10:25:09] "OPTIONS /employee/login HTTP/1.1" 200 -
2021-12-23 10:25:10,785 INFO 127.0.0.1 - - [23/Dec/2021 10:25:10] "OPTIONS /employee/login HTTP/1.1" 200 -
2021-12-23 10:25:11,094 INFO 127.0.0.1 - - [23/Dec/2021 10:25:11] "OPTIONS /employee/login HTTP/1.1" 200 -
2021-12-23 10:25:11,327 INFO 127.0.0.1 - - [23/Dec/2021 10:25:11] "OPTIONS /employee/login HTTP/1.1" 200 -
2021-12-23 10:25:11,586 INFO 127.0.0.1 - - [23/Dec/2021 10:25:11] "OPTIONS /employee/login HTTP/1.1" 200 -
2021-12-23 10:25:12,112 INFO 127.0.0.1 - - [23/Dec/2021 10:25:12] "OPTIONS /employee/login HTTP/1.1" 200 -
2021-12-23 10:30:51,943 INFO 127.0.0.1 - - [23/Dec/2021 10:30:51] "OPTIONS /employee/login HTTP/1.1" 200 -
2021-12-23 10:30:52,440 INFO 127.0.0.1 - - [23/Dec/2021 10:30:52] "OPTIONS /employee/login HTTP/1.1" 200 -
2021-12-23 10:30:52,611 INFO 127.0.0.1 - - [23/Dec/2021 10:30:52] "OPTIONS /employee/login HTTP/1.1" 200 -
2021-12-23 10:30:52,782 INFO 127.0.0.1 - - [23/Dec/2021 10:30:52] "OPTIONS /employee/login HTTP/1.1" 200 -
2021-12-23 10:30:52,952 INFO 127.0.0.1 - - [23/Dec/2021 10:30:52] "OPTIONS /employee/login HTTP/1.1" 200 -
2021-12-23 10:30:53,123 INFO 127.0.0.1 - - [23/Dec/2021 10:30:53] "OPTIONS /employee/login HTTP/1.1" 200 -
2021-12-23 10:30:53,293 INFO 127.0.0.1 - - [23/Dec/2021 10:30:53] "OPTIONS /employee/login HTTP/1.1" 200 -
2021-12-23 10:30:53,456 INFO 127.0.0.1 - - [23/Dec/2021 10:30:53] "OPTIONS /employee/login HTTP/1.1" 200 -
2021-12-23 10:30:53,642 INFO 127.0.0.1 - - [23/Dec/2021 10:30:53] "OPTIONS /employee/login HTTP/1.1" 200 -
2021-12-23 10:30:53,849 INFO 127.0.0.1 - - [23/Dec/2021 10:30:53] "OPTIONS /employee/login HTTP/1.1" 200 -
2021-12-23 10:30:59,608 INFO 127.0.0.1 - - [23/Dec/2021 10:30:59] "OPTIONS /employee/login HTTP/1.1" 200 -
2021-12-23 10:30:59,771 INFO 127.0.0.1 - - [23/Dec/2021 10:30:59] "OPTIONS /employee/login HTTP/1.1" 200 -
2021-12-23 10:31:04,258 INFO 127.0.0.1 - - [23/Dec/2021 10:31:04] "OPTIONS /employee/login HTTP/1.1" 200 -
2021-12-23 10:31:04,463 INFO 127.0.0.1 - - [23/Dec/2021 10:31:04] "OPTIONS /employee/login HTTP/1.1" 200 -
2021-12-23 10:31:04,648 INFO 127.0.0.1 - - [23/Dec/2021 10:31:04] "OPTIONS /employee/login HTTP/1.1" 200 -
2021-12-23 10:31:05,057 INFO 127.0.0.1 - - [23/Dec/2021 10:31:05] "OPTIONS /employee/login HTTP/1.1" 200 -
2021-12-23 10:31:05,227 INFO 127.0.0.1 - - [23/Dec/2021 10:31:05] "OPTIONS /employee/login HTTP/1.1" 200 -
